Workbook

Sheet 기입요령
A1: CREDEAL 렌트롤 표준 양식 v1.5 — 기입요령
A3: 모바일 IM 업로드용 표준 양식입니다. 「렌트롤」 시트의 노란색 셀만 입력하세요. (1행 = 1호실, 최대 100호실)
A5: 계약그룹이란? — 한 임차인이 한 계약서로 여러 호실·층을 쓰는 경우 (통합계약)
A6: 뜻 | B6: 하나의 임대차계약서로 한 임차인이 여러 호실(예: 1F+2F)을 쓸 때, 그 호실들을 한 묶음으로 표시하는 이름표입니다. 호실마다 따로 계약했다면 비워 두세요.
A7: 쓰는 법 | B7: 같은 계약에 속한 호실에는 같은 이름(A, B, 1 …)을 적습니다. 이름은 자유이며, 서로 다른 계약은 다른 이름으로 구분합니다.
A8: 금액은 대표 행에만 | B8: 보증금·월세·관리비는 묶음 중 한 행(대표 행)에만 적고 나머지 행은 비웁니다. 면적(임대·전용)·호실/층·업종/상호·임대상태·만료일·적용법령·최초 계약일·대항력 요건·근거는 행마다 적습니다 (v1.4 명확화).
A9: 예시 (설명용) | B9: 1F │ 그룹 A │ 임대 100㎡ │ ○○카페 │ 보증금·월세 입력 ← 대표 행 2F │ 그룹 A │ 임대 80㎡ │ ○○카페 │ 보증금·월세 비움 ← 같은 계약 3F │ (비움) │ 임대 90㎡ │ △△법무법인 │ 보증금·월세 입력 ← 단독 계약
A10: 왜 필요한가 | B10: 금액을 층마다 쪼개 적으면 한 계약이 여러 건으로 집계되고 환산보증금(상가법 적용 판정)이 쪼개져 틀어집니다. 대표 행에만 적으면 합계·환산보증금이 계약 1건으로 계산됩니다.
A11: IM에서의 표기 | B11: IM 렌트롤 표에서 같은 그룹의 금액 빈 행은 보증금·월임대료·관리비·월합계가 「〃」(위와 동일 계약)로 표시되고, 합계에는 대표 행 금액만 더해집니다. 계약그룹은 업로드 후 원장(lease_ledger)에도 저장됩니다.
A13: 색상 규칙
A14: 노란색 | B14: 입력 셀 — 여기만 채웁니다.
A15: 회색 | B15: 자동계산 — 수식이 들어 있으니 건드리지 마세요.
A16: 파랑/주황/분홍 (11행) | B16: 해상도 표시: 주황=R1 발행 최소선 · 파랑=R2 분석 가능 · 분홍=R3 정밀 실사. 자세한 정의는 「컬럼정의」 시트.
A18: 해상도(R1·R2·R3) — 채울수록 열리는 기능이 늘어납니다
A19: R1 최소형 | B19: 호실·업종·보증금·월세·만료일·임대상태 → 렌트롤 표 · 만료 타임라인 · 총액 수익률
A20: R2 필요형 | B20: R1 + 임대면적·적용법령·관리비 → 평당 단가 · 층별 단가 · 환산보증금 · 상임법 판정
A21: R3 표준형 | B21: R2 + 최초 계약일·대항력 → 갱신요구권 · 명도 계획 · 임대료 정상화 시뮬
A22: 면적 보강 (등급 무관) | B22: 전 호실 전용면적 입력(전용 ≤ 임대) → 전용률 · 전용평당 월비용(NOC)
A24: 면적 3종 — 임대면적 · 전용면적 · 전용률
A25: 임대면적 (C열) | B25: 임대차계약서에 적힌 계약면적. 전용면적 + 공용면적 분담분입니다. 임대료 평당 단가·공실률의 분모이며, 공실·자가사용 호실도 적습니다. 단위는 G9에서 고른 단위(㎡ 또는 평).
A26: 전용면적 (D열) | B26: 임차인이 독점해 사용하는 면적. 건축물대장 전유부 면적과 대조하세요. 임대면적보다 클 수 없습니다. 단위는 임대면적과 같습니다(G9).
A27: 전용률 (S열, 자동) | B27: 전용면적 ÷ 임대면적 × 100. 직접 입력하지 마세요. 합계 행(10행)의 전용률은 평균이 아니라 Σ전용 ÷ Σ임대(두 면적이 모두 있는 호실만)입니다.
A28: 단위 | B28: 면적 단위는 「렌트롤」 시트 G9에서 ㎡ 또는 평을 고릅니다(기본 ㎡). 고른 단위로 C·D열을 적으면 AE·AF열이 ㎡로, Q·R열이 평으로 자동 환산됩니다. 한 파일에는 한 단위만 씁니다. 숫자를 적은 뒤 단위를 바꾸면 숫자는 바뀌지 않고 뜻만 바뀌니 처음에 고르세요. 연면적(J4)은 건축물대장 값이라 ㎡ 고정입니다.
A29: IM 표 표기 | B29: IM 렌트롤 표에는 입력한 면적만 나옵니다. 임대·전용면적을 모두 적으면 두 열, 하나만 적으면 그 열 하나만 표시합니다. 한 면적을 다른 면적 값으로 대신 채우지 않고, 비워 둔 호실은 「-」로 표시합니다.
A30: 전용면적을 모를 때 | B30: 임대면적만 입력해도 업로드됩니다. 전용률·전용평당 월비용만 보류되고 IM 표에는 임대면적 열만 나옵니다 (「자동검증」에 미기재 호실 수가 표시됩니다).
A32: 반드시 채워야 하는 항목 (R1)
A33: 호실/층 | B33: 원본 표기 그대로. 「9F(1)」처럼 한 층에 둘이면 행을 나눠 적습니다.
A34: 업종/상호 (원문) | B34: ⚠ 계약서·렌트롤에 적힌 문구를 그대로 옮깁니다. 「사무실」이면 「사무실」입니다. 업종을 추측해 바꾸지 마세요.
A35: 임대상태 | B35: 임대중 / 공실 / 자가사용. 소유자가 직접 쓰는 층은 「자가사용」 — 공실이 아니지만 임대수입도 없습니다.
A36: 보증금·월세·관리비 | B36: 원 단위 숫자만. VAT 별도. 「5,000만」처럼 적지 마세요 (5,000만원 → 50000000).
A37: 현 계약 만료일 | B37: 명도 시점·만기 스케줄 산출의 기준입니다. 날짜 형식은 YYYY-MM-DD.
A39: 비면 판정이 보류되는 항목 (R2·R3)
A40: 적용법령 (R2) | B40: 상가 / 주택 / 미확인. 주거로 쓰는 오피스텔은 「주택」입니다. 이 값에 따라 갱신요구권 계산이 완전히 달라집니다.
A41: 최초 계약일 (R3) | B41: 이 임차인이 처음 입주한 날. 현 계약 시작일과 다릅니다. ★ 상가 갱신요구권 10년은 이 날짜로 기산합니다. 비면 「확인 필요」로 출력됩니다.
A42: 갱신요구권 행사 (R3) | B42: 있음 / 없음 / 모름. ★ 주택은 1회 한정이라 이 값 없이는 계산할 수 없습니다. 묵시적 갱신은 「없음」입니다 — 갱신요구권을 쓴 것이 아닙니다.
A43: 대항력 요건 (R3) | B43: 사업자등록 / 주민등록 / 미확인. 근거 없이 「없음」으로 적으면 발행이 막힙니다.
A45: 자주 나는 실수
A46: 업종 추측 | B46: 「사무실」을 「IT스타트업」으로 바꿔 적는 경우. 실제로 있었던 오류입니다.
A47: 면적 혼동 | B47: 전용면적을 임대면적 칸에 적거나, G9 단위와 다른 단위로 적는 경우. 전용률이 100%를 넘으면(빨간색) 두 칸이 바뀌었는지, 자동검증 V12가 ⚠이면 단위가 섞였는지 확인하세요.
A48: 경과년수로 갱신권 역산 | B48: 주택은 최초계약일로 계산할 수 없습니다. 행사 이력이 있어야 합니다.
...

Sheet 렌트롤
A1: CREDEAL 렌트롤 표준 양식 v1.5
A2: 노란색 셀만 입력 · 회색은 자동계산 · 1행=1호실 · 면적 단위는 G9에서 ㎡/평 선택(기본 ㎡) · 금액 원(VAT 별도) · 11행 R1/R2/R3 = 해상도 · v1.5: 면적 입력 단위 선택, AE·AF열 ㎡ 환산(정본)
A3: 물건명 | C3: 잠원동 개발부지 | F3: ⚠ 렌트롤 기준일이 비면 신선도 판정을 할 수 없습니다 | H3: 매각(희망)가(원) | J3: 24226800000 | L3: 수익률 계산용. 비우면 자동검증의 수익률이 보류됩니다
A4: 소재지 | C4: 서울특별시 서초구 잠원동 26-14, 16번지 | F4: ※ 환산보증금: 서울 9억 · 과밀억제권역 6.9억 · 광역시 5.4억 · 그 밖 3.7억 | H4: 연면적(㎡ 고정, 건축물대장) | J4: 2032.59 | L4: 공부 API 값(㎡). 임대면적 합계와 대조합니다 — G9 단위와 무관
A5: 렌트롤 기준일 | C5: 46300 | H5: 시장 임대료 1층(원/전용평·월) | L5: 출처·조사일 →
A6: 평가 기준일 | C6: =IF(C5="",TODAY(),C5) | F6: 자동 = 렌트롤 기준일(C5). C5가 비면 TODAY()로 대체되어 열 때마다 값이 바뀝니다 | H6: 시장 임대료 지상층(원/전용평·월) | L6: 출처·조사일 →
A7: 환산보증금 지역기준(원) | C7: 900000000 | F7: 지역에 맞게 수정 (서울 900,000,000) | H7: 시장 임대료 지하층(원/전용평·월) | L7: 출처·조사일 →
A8: 작성자 | H8: 기타수입(원/월, VAT별도) | L8: 내역 (예: 안테나·주차·광고) →
A9: 작성일 | F9: 면적 단위 ▶ | G9: ㎡ | H9: IM 연계 입력 (v1.4) — 분홍 칸은 R3 고품질 IM(임대료 정상화 시뮬)용
A10: 합계 (자동) | C10: =SUM(C13:C112) | D10: =SUM(D13:D112) | G10: =SUM(G13:G112) | H10: =SUM(H13:H112) | I10: =SUM(I13:I112) | Q10: =SUM(Q13:Q112) | R10: =SUM(R13:R112) | S10: =IFERROR(SUMIFS(D13:D112,C13:C112,">0",D13:D112,">0")/SUMIFS(C13:C112,C13:C112,">0",D13:D112,">0")*100,"") | X10: =SUM(X13:X112) | AE10: =SUM(AE13:AE112) | AF10: =SUM(AF13:AF112)
A11: R1 | B11: R2 | C11: R2 | D11: R2* | E11: R1 | F11: R2 | G11: R1 | H11: R1 | I11: R2 | J11: R3 | K11: R2 | L11: R1 | M11: R3 | N11: R3 | O11: R1 | P11: — | Q11: 자동 | R11: 자동 | S11: 자동 | T11: 자동 | U11: 자동 | V11: 자동 | W11: 자동 | X11: 자동 | Y11: 자동 | Z11: R3+ | AA11: R3+ | AB11: R3+ | AC11: 자동 | AD11: 자동 | AE11: 자동 | AF11: 자동
A12: 호실/층 | B12: 계약그룹 | C12: ="임대면적("&$G$9&")" | D12: ="전용면적("&$G$9&")" | E12: 업종/상호 (원문) | F12: 적용법령 | G12: 보증금(원) | H12: 월세(원,VAT별도) | I12: 관리비(원,VAT별도) | J12: 최초 계약일 | K12: 현 계약 시작일 | L12: 현 계약 만료일 | M12: 갱신요구권 행사 | N12: 대항력 요건 | O12: 임대상태 | P12: 비고 | Q12: 임대면적(평) | R12: 전용면적(평) | S12: 전용률(%) | T12: 환산보증금(자동) | U12: 상임법 전면적용 | V12: 갱신권 잔여(자동) | W12: 계약 상태(자동) | X12: 월 총수입(자동) | Y12: 전용평당 월비용(자동) | Z12: 근거 | AA12: 렌트프리 잔여(개월) | AB12: 입금 확인(최근12개월) | AC12: 만기 구간(자동) | AD12: 금액 판정(자동) | AE12: 임대면적(㎡ 환산) | AF12: 전용면적(㎡ 환산)
A13: B1 | C13: 318.78 | E13: 주점 | G13: 340000000 | H13: 3370000 | I13: 290000 | K13: 43525 | L13: 46477 | O13: 임대중 | P13: 협의 중 | Q13: =IF(OR($A13="",C13=""),"",AE13/3.305785) | R13: =IF(OR($A13="",D13=""),"",AF13/3.305785) | S13: =IF(OR($A13="",C13="",D13=""),"",IF(C13>0,D13/C13*100,"")) | T13: =IF(OR($A13="",O13<>"임대중",F13<>"상가",G13=""),"",G13+H13*100) | U13: =IF(T13="","",IF(T13<=$C$7,"○ 전면적용","× 초과 (5%상한 미적용)")) | V13: =IF(OR($A13="",O13<>"임대중"),"",IF(F13="상가",IF(J13="","확인 필요",TEXT(MAX(0,10-($C$6-J13)/365.25),"0.0")&"년"),IF(F13="주택",IF(M13="있음","소진(1회)",IF(M13="없음",IF(L13="","확인 필요",TEXT(EDATE(L13,24),"yyyy-mm")&"까지"),"확인 필요")),"확인 필요"))) | W13: =IF($A13="","",IF(O13="공실","공실",IF(O13="자가사용","자가사용",IF(L13="","만료일 없음",IF(L13<$C$6,"만료 +"&TEXT($C$6-L13,"0")&"일",IF(L13-$C$6<=30,"임박 "&TEXT(L13-$C$6,"0")&"일","유효")))))) | X13: =IF(OR($A13="",O13<>"임대중"),"",IF(H13="",0,H13)+IF(I13="",0,I13)) | Y13: =IF(OR($A13="",O13<>"임대중",H13=""),"",IF(B13="",IF(D13="","",ROUND((H13+IF(I13="",0,I13))/(AF13/3.305785),0)),IF(COUNTIFS($B$13:$B$112,B13,$D$13:$D$112,"")>0,"",ROUND((H13+IF(I13="",0,I13))/(SUMIFS($AF$13:$AF$112,$B$13:$B$112,B13)/3.305785),0)))) | AC13: =IF($A13="","",IF(O13="공실","공실",IF(O13="자가사용","자가사용",IF(L13="","만료일 없음",IF(L13<$C$6,"만료 경과",IF(L13<=EDATE($C$6,12),"12개월 내","12개월 초과")))))) | AD13: =IF(OR($A13="",O13<>"임대중"),"",IF(B13="",IF(H13="","월세 누락",IF(I13="","관리비 누락","OK")),IF(COUNTIFS($B$13:$B$112,B13,$H$13:$H$112,"<>")>1,"금액 중복",IF(COUNTIFS($B$13:$B$112,B13,$H$13:$H$112,"<>")=0,"월세 누락",IF(COUNTIFS($B$13:$B$112,B13,$I$13:$I$112,"<>")=0,"관리비 누락","OK"))))) | AE13: =IF(OR($A13="",C13=""),"",ROUND(C13*IF($G$9="평",3.305785,1),2)) | AF13: =IF(OR($A13="",D13=""),"",ROUND(D13*IF($G$9="평",3.305785,1),2))
A14: B1 | C14: 145.79 | E14: 창고 | G14: 60000000 | H14: 880000 | I14: 130000 | K14: 42156 | L14: 46387 | O14: 임대중 | P14: 합의 완료 | Q14: =IF(OR($A14="",C14=""),"",AE14/3.305785) | R14: =IF(OR($A14="",D14=""),"",AF14/3.305785) | S14: =IF(OR($A14="",C14="",D14=""),"",IF(C14>0,D14/C14*100,"")) | T14: =IF(OR($A14="",O14<>"임대중",F14<>"상가",G14=""),"",G14+H14*100) | U14: =IF(T14="","",IF(T14<=$C$7,"○ 전면적용","× 초과 (5%상한 미적용)")) | V14: =IF(OR($A14="",O14<>"임대중"),"",IF(F14="상가",IF(J14="","확인 필요",TEXT(MAX(0,10-($C$6-J14)/365.25),"0.0")&"년"),IF(F14="주택",IF(M14="있음","소진(1회)",IF(M14="없음",IF(L14="","확인 필요",TEXT(EDATE(L14,24),"yyyy-mm")&"까지"),"확인 필요")),"확인 필요"))) | W14: =IF($A14="","",IF(O14="공실","공실",IF(O14="자가사용","자가사용",IF(L14="","만료일 없음",IF(L14<$C$6,"만료 +"&TEXT($C$6-L14,"0")&"일",IF(L14-$C$6<=30,"임박 "&TEXT(L14-$C$6,"0")&"일","유효")))))) | X14: =IF(OR($A14="",O14<>"임대중"),"",IF(H14="",0,H14)+IF(I14="",0,I14)) | Y14: =IF(OR($A14="",O14<>"임대중",H14=""),"",IF(B14="",IF(D14="","",ROUND((H14+IF(I14="",0,I14))/(AF14/3.305785),0)),IF(COUNTIFS($B$13:$B$112,B14,$D$13:$D$112,"")>0,"",ROUND((H14+IF(I14="",0,I14))/(SUMIFS($AF$13:$AF$112,$B$13:$B$112,B14)/3.305785),0)))) | AC14: =IF($A14="","",IF(O14="공실","공실",IF(O14="자가사용","자가사용",IF(L14="","만료일 없음",IF(L14<$C$6,"만료 경과",IF(L14<=EDATE($C$6,12),"12개월 내","12개월 초과")))))) | AD14: =IF(OR($A14="",O14<>"임대중"),"",IF(B14="",IF(H14="","월세 누락",IF(I14="","관리비 누락","OK")),IF(COUNTIFS($B$13:$B$112,B14,$H$13:$H$112,"<>")>1,"금액 중복",IF(COUNTIFS($B$13:$B$112,B14,$H$13:$H$112,"<>")=0,"월세 누락",IF(COUNTIFS($B$13:$B$112,B14,$I$13:$I$112,"<>")=0,"관리비 누락","OK"))))) | AE14: =IF(OR($A14="",C14=""),"",ROUND(C14*IF($G$9="평",3.305785,1),2)) | AF14: =IF(OR($A14="",D14=""),"",ROUND(D14*IF($G$9="평",3.305785,1),2))
A15: 1F | C15: 103.7 | E15: 소매점 | G15: 50000000 | H15: 4700000 | I15: 100000 | K15: 44805 | L15: 46660 | O15: 임대중 | P15: 미협의 | Q15: =IF(OR($A15="",C15=""),"",AE15/3.305785) | R15: =IF(OR($A15="",D15=""),"",AF15/3.305785) | S15: =IF(OR($A15="",C15="",D15=""),"",IF(C15>0,D15/C15*100,"")) | T15: =IF(OR($A15="",O15<>"임대중",F15<>"상가",G15=""),"",G15+H15*100) | U15: =IF(T15="","",IF(T15<=$C$7,"○ 전면적용","× 초과 (5%상한 미적용)")) | V15: =IF(OR($A15="",O15<>"임대중"),"",IF(F15="상가",IF(J15="","확인 필요",TEXT(MAX(0,10-($C$6-J15)/365.25),"0.0")&"년"),IF(F15="주택",IF(M15="있음","소진(1회)",IF(M15="없음",IF(L15="","확인 필요",TEXT(EDATE(L15,24),"yyyy-mm")&"까지"),"확인 필요")),"확인 필요"))) | W15: =IF($A15="","",IF(O15="공실","공실",IF(O15="자가사용","자가사용",IF(L15="","만료일 없음",IF(L15<$C$6,"만료 +"&TEXT($C$6-L15,"0")&"일",IF(L15-$C$6<=30,"임박 "&TEXT(L15-$C$6,"0")&"일","유효")))))) | X15: =IF(OR($A15="",O15<>"임대중"),"",IF(H15="",0,H15)+IF(I15="",0,I15)) | Y15: =IF(OR($A15="",O15<>"임대중",H15=""),"",IF(B15="",IF(D15="","",ROUND((H15+IF(I15="",0,I15))/(AF15/3.305785),0)),IF(COUNTIFS($B$13:$B$112,B15,$D$13:$D$112,"")>0,"",ROUND((H15+IF(I15="",0,I15))/(SUMIFS($AF$13:$AF$112,$B$13:$B$112,B15)/3.305785),0)))) | AC15: =IF($A15="","",IF(O15="공실","공실",IF(O15="자가사용","자가사용",IF(L15="","만료일 없음",IF(L15<$C$6,"만료 경과",IF(L15<=EDATE($C$6,12),"12개월 내","12개월 초과")))))) | AD15: =IF(OR($A15="",O15<>"임대중"),"",IF(B15="",IF(H15="","월세 누락",IF(I15="","관리비 누락","OK")),IF(COUNTIFS($B$13:$B$112,B15,$H$13:$H$112,"<>")>1,"금액 중복",IF(COUNTIFS($B$13:$B$112,B15,$H$13:$H$112,"<>")=0,"월세 누락",IF(COUNTIFS($B$13:$B$112,B15,$I$13:$I$112,"<>")=0,"관리비 누락","OK"))))) | AE15: =IF(OR($A15="",C15=""),"",ROUND(C15*IF($G$9="평",3.305785,1),2)) | AF15: =IF(OR($A15="",D15=""),"",ROUND(D15*IF($G$9="평",3.305785,1),2))
A16: 1F | C16: 93.06 | E16: 휴게음식점 | G16: 80000000 | H16: 3500000 | I16: 80000 | K16: 44197 | L16: 46387 | O16: 임대중 | P16: 합의 완료 | Q16: =IF(OR($A16="",C16=""),"",AE16/3.305785) | R16: =IF(OR($A16="",D16=""),"",AF16/3.305785) | S16: =IF(OR($A16="",C16="",D16=""),"",IF(C16>0,D16/C16*100,"")) | T16: =IF(OR($A16="",O16<>"임대중",F16<>"상가",G16=""),"",G16+H16*100) | U16: =IF(T16="","",IF(T16<=$C$7,"○ 전면적용","× 초과 (5%상한 미적용)")) | V16: =IF(OR($A16="",O16<>"임대중"),"",IF(F16="상가",IF(J16="","확인 필요",TEXT(MAX(0,10-($C$6-J16)/365.25),"0.0")&"년"),IF(F16="주택",IF(M16="있음","소진(1회)",IF(M16="없음",IF(L16="","확인 필요",TEXT(EDATE(L16,24),"yyyy-mm")&"까지"),"확인 필요")),"확인 필요"))) | W16: =IF($A16="","",IF(O16="공실","공실",IF(O16="자가사용","자가사용",IF(L16="","만료일 없음",IF(L16<$C$6,"만료 +"&TEXT($C$6-L16,"0")&"일",IF(L16-$C$6<=30,"임박 "&TEXT(L16-$C$6,"0")&"일","유효")))))) | X16: =IF(OR($A16="",O16<>"임대중"),"",IF(H16="",0,H16)+IF(I16="",0,I16)) | Y16: =IF(OR($A16="",O16<>"임대중",H16=""),"",IF(B16="",IF(D16="","",ROUND((H16+IF(I16="",0,I16))/(AF16/3.305785),0)),IF(COUNTIFS($B$13:$B$112,B16,$D$13:$D$112,"")>0,"",ROUND((H16+IF(I16="",0,I16))/(SUMIFS($AF$13:$AF$112,$B$13:$B$112,B16)/3.305785),0)))) | AC16: =IF($A16="","",IF(O16="공실","공실",IF(O16="자가사용","자가사용",IF(L16="","만료일 없음",IF(L16<$C$6,"만료 경과",IF(L16<=EDATE($C$6,12),"12개월 내","12개월 초과")))))) | AD16: =IF(OR($A16="",O16<>"임대중"),"",IF(B16="",IF(H16="","월세 누락",IF(I16="","관리비 누락","OK")),IF(COUNTIFS($B$13:$B$112,B16,$H$13:$H$112,"<>")>1,"금액 중복",IF(COUNTIFS($B$13:$B$112,B16,$H$13:$H$112,"<>")=0,"월세 누락",IF(COUNTIFS($B$13:$B$112,B16,$I$13:$I$112,"<>")=0,"관리비 누락","OK"))))) | AE16: =IF(OR($A16="",C16=""),"",ROUND(C16*IF($G$9="평",3.305785,1),2)) | AF16: =IF(OR($A16="",D16=""),"",ROUND(D16*IF($G$9="평",3.305785,1),2))
A17: 1F | C17: 32 | E17: 부동산중개 | G17: 30000000 | H17: 1500000 | I17: 30000 | K17: 44986 | L17: 45716 | O17: 임대중 | P17: 만기퇴거 | Q17: =IF(OR($A17="",C17=""),"",AE17/3.305785) | R17: =IF(OR($A17="",D17=""),"",AF17/3.305785) | S17: =IF(OR($A17="",C17="",D17=""),"",IF(C17>0,D17/C17*100,"")) | T17: =IF(OR($A17="",O17<>"임대중",F17<>"상가",G17=""),"",G17+H17*100) | U17: =IF(T17="","",IF(T17<=$C$7,"○ 전면적용","× 초과 (5%상한 미적용)")) | V17: =IF(OR($A17="",O17<>"임대중"),"",IF(F17="상가",IF(J17="","확인 필요",TEXT(MAX(0,10-($C$6-J17)/365.25),"0.0")&"년"),IF(F17="주택",IF(M17="있음","소진(1회)",IF(M17="없음",IF(L17="","확인 필요",TEXT(EDATE(L17,24),"yyyy-mm")&"까지"),"확인 필요")),"확인 필요"))) | W17: =IF($A17="","",IF(O17="공실","공실",IF(O17="자가사용","자가사용",IF(L17="","만료일 없음",IF(L17<$C$6,"만료 +"&TEXT($C$6-L17,"0")&"일",IF(L17-$C$6<=30,"임박 "&TEXT(L17-$C$6,"0")&"일","유효")))))) | X17: =IF(OR($A17="",O17<>"임대중"),"",IF(H17="",0,H17)+IF(I17="",0,I17)) | Y17: =IF(OR($A17="",O17<>"임대중",H17=""),"",IF(B17="",IF(D17="","",ROUND((H17+IF(I17="",0,I17))/(AF17/3.305785),0)),IF(COUNTIFS($B$13:$B$112,B17,$D$13:$D$112,"")>0,"",ROUND((H17+IF(I17="",0,I17))/(SUMIFS($AF$13:$AF$112,$B$13:$B$112,B17)/3.305785),0)))) | AC17: =IF($A17="","",IF(O17="공실","공실",IF(O17="자가사용","자가사용",IF(L17="","만료일 없음",IF(L17<$C$6,"만료 경과",IF(L17<=EDATE($C$6,12),"12개월 내","12개월 초과")))))) | AD17: =IF(OR($A17="",O17<>"임대중"),"",IF(B17="",IF(H17="","월세 누락",IF(I17="","관리비 누락","OK")),IF(COUNTIFS($B$13:$B$112,B17,$H$13:$H$112,"<>")>1,"금액 중복",IF(COUNTIFS($B$13:$B$112,B17,$H$13:$H$112,"<>")=0,"월세 누락",IF(COUNTIFS($B$13:$B$112,B17,$I$13:$I$112,"<>")=0,"관리비 누락","OK"))))) | AE17: =IF(OR($A17="",C17=""),"",ROUND(C17*IF($G$9="평",3.305785,1),2)) | AF17: =IF(OR($A17="",D17=""),"",ROUND(D17*IF($G$9="평",3.305785,1),2))
A18: 2F | C18: 266.38 | E18: 일반음식점 | G18: 150000000 | H18: 5000000 | I18: 240000 | K18: 43952 | L18: 46142 | O18: 임대중 | Q18: =IF(OR($A18="",C18=""),"",AE18/3.305785) | R18: =IF(OR($A18="",D18=""),"",AF18/3.305785) | S18: =IF(OR($A18="",C18="",D18=""),"",IF(C18>0,D18/C18*100,"")) | T18: =IF(OR($A18="",O18<>"임대중",F18<>"상가",G18=""),"",G18+H18*100) | U18: =IF(T18="","",IF(T18<=$C$7,"○ 전면적용","× 초과 (5%상한 미적용)")) | V18: =IF(OR($A18="",O18<>"임대중"),"",IF(F18="상가",IF(J18="","확인 필요",TEXT(MAX(0,10-($C$6-J18)/365.25),"0.0")&"년"),IF(F18="주택",IF(M18="있음","소진(1회)",IF(M18="없음",IF(L18="","확인 필요",TEXT(EDATE(L18,24),"yyyy-mm")&"까지"),"확인 필요")),"확인 필요"))) | W18: =IF($A18="","",IF(O18="공실","공실",IF(O18="자가사용","자가사용",IF(L18="","만료일 없음",IF(L18<$C$6,"만료 +"&TEXT($C$6-L18,"0")&"일",IF(L18-$C$6<=30,"임박 "&TEXT(L18-$C$6,"0")&"일","유효")))))) | X18: =IF(OR($A18="",O18<>"임대중"),"",IF(H18="",0,H18)+IF(I18="",0,I18)) | Y18: =IF(OR($A18="",O18<>"임대중",H18=""),"",IF(B18="",IF(D18="","",ROUND((H18+IF(I18="",0,I18))/(AF18/3.305785),0)),IF(COUNTIFS($B$13:$B$112,B18,$D$13:$D$112,"")>0,"",ROUND((H18+IF(I18="",0,I18))/(SUMIFS($AF$13:$AF$112,$B$13:$B$112,B18)/3.305785),0)))) | AC18: =IF($A18="","",IF(O18="공실","공실",IF(O18="자가사용","자가사용",IF(L18="","만료일 없음",IF(L18<$C$6,"만료 경과",IF(L18<=EDATE($C$6,12),"12개월 내","12개월 초과")))))) | AD18: =IF(OR($A18="",O18<>"임대중"),"",IF(B18="",IF(H18="","월세 누락",IF(I18="","관리비 누락","OK")),IF(COUNTIFS($B$13:$B$112,B18,$H$13:$H$112,"<>")>1,"금액 중복",IF(COUNTIFS($B$13:$B$112,B18,$H$13:$H$112,"<>")=0,"월세 누락",IF(COUNTIFS($B$13:$B$112,B18,$I$13:$I$112,"<>")=0,"관리비 누락","OK"))))) | AE18: =IF(OR($A18="",C18=""),"",ROUND(C18*IF($G$9="평",3.305785,1),2)) | AF18: =IF(OR($A18="",D18=""),"",ROUND(D18*IF($G$9="평",3.305785,1),2))
A19: 3F-1 | C19: 135.6 | E19: 사무소 | G19: 50000000 | H19: 2500000 | I19: 120000 | O19: 임대중 | Q19: =IF(OR($A19="",C19=""),"",AE19/3.305785) | R19: =IF(OR($A19="",D19=""),"",AF19/3.305785) | S19: =IF(OR($A19="",C19="",D19=""),"",IF(C19>0,D19/C19*100,"")) | T19: =IF(OR($A19="",O19<>"임대중",F19<>"상가",G19=""),"",G19+H19*100) | U19: =IF(T19="","",IF(T19<=$C$7,"○ 전면적용","× 초과 (5%상한 미적용)")) | V19: =IF(OR($A19="",O19<>"임대중"),"",IF(F19="상가",IF(J19="","확인 필요",TEXT(MAX(0,10-($C$6-J19)/365.25),"0.0")&"년"),IF(F19="주택",IF(M19="있음","소진(1회)",IF(M19="없음",IF(L19="","확인 필요",TEXT(EDATE(L19,24),"yyyy-mm")&"까지"),"확인 필요")),"확인 필요"))) | W19: =IF($A19="","",IF(O19="공실","공실",IF(O19="자가사용","자가사용",IF(L19="","만료일 없음",IF(L19<$C$6,"만료 +"&TEXT($C$6-L19,"0")&"일",IF(L19-$C$6<=30,"임박 "&TEXT(L19-$C$6,"0")&"일","유효")))))) | X19: =IF(OR($A19="",O19<>"임대중"),"",IF(H19="",0,H19)+IF(I19="",0,I19)) | Y19: =IF(OR($A19="",O19<>"임대중",H19=""),"",IF(B19="",IF(D19="","",ROUND((H19+IF(I19="",0,I19))/(AF19/3.305785),0)),IF(COUNTIFS($B$13:$B$112,B19,$D$13:$D$112,"")>0,"",ROUND((H19+IF(I19="",0,I19))/(SUMIFS($AF$13:$AF$112,$B$13:$B$112,B19)/3.305785),0)))) | AC19: =IF($A19="","",IF(O19="공실","공실",IF(O19="자가사용","자가사용",IF(L19="","만료일 없음",IF(L19<$C$6,"만료 경과",IF(L19<=EDATE($C$6,12),"12개월 내","12개월 초과")))))) | AD19: =IF(OR($A19="",O19<>"임대중"),"",IF(B19="",IF(H19="","월세 누락",IF(I19="","관리비 누락","OK")),IF(COUNTIFS($B$13:$B$112,B19,$H$13:$H$112,"<>")>1,"금액 중복",IF(COUNTIFS($B$13:$B$112,B19,$H$13:$H$112,"<>")=0,"월세 누락",IF(COUNTIFS($B$13:$B$112,B19,$I$13:$I$112,"<>")=0,"관리비 누락","OK"))))) | AE19: =IF(OR($A19="",C19=""),"",ROUND(C19*IF($G$9="평",3.305785,1),2)) | AF19: =IF(OR($A19="",D19=""),"",ROUND(D19*IF($G$9="평",3.305785,1),2))
A20: 3F-2 | C20: 130.74 | E20: 의원 | G20: 70000000 | H20: 3000000 | I20: 120000 | O20: 임대중 | Q20: =IF(OR($A20="",C20=""),"",AE20/3.305785) | R20: =IF(OR($A20="",D20=""),"",AF20/3.305785) | S20: =IF(OR($A20="",C20="",D20=""),"",IF(C20>0,D20/C20*100,"")) | T20: =IF(OR($A20="",O20<>"임대중",F20<>"상가",G20=""),"",G20+H20*100) | U20: =IF(T20="","",IF(T20<=$C$7,"○ 전면적용","× 초과 (5%상한 미적용)")) | V20: =IF(OR($A20="",O20<>"임대중"),"",IF(F20="상가",IF(J20="","확인 필요",TEXT(MAX(0,10-($C$6-J20)/365.25),"0.0")&"년"),IF(F20="주택",IF(M20="있음","소진(1회)",IF(M20="없음",IF(L20="","확인 필요",TEXT(EDATE(L20,24),"yyyy-mm")&"까지"),"확인 필요")),"확인 필요"))) | W20: =IF($A20="","",IF(O20="공실","공실",IF(O20="자가사용","자가사용",IF(L20="","만료일 없음",IF(L20<$C$6,"만료 +"&TEXT($C$6-L20,"0")&"일",IF(L20-$C$6<=30,"임박 "&TEXT(L20-$C$6,"0")&"일","유효")))))) | X20: =IF(OR($A20="",O20<>"임대중"),"",IF(H20="",0,H20)+IF(I20="",0,I20)) | Y20: =IF(OR($A20="",O20<>"임대중",H20=""),"",IF(B20="",IF(D20="","",ROUND((H20+IF(I20="",0,I20))/(AF20/3.305785),0)),IF(COUNTIFS($B$13:$B$112,B20,$D$13:$D$112,"")>0,"",ROUND((H20+IF(I20="",0,I20))/(SUMIFS($AF$13:$AF$112,$B$13:$B$112,B20)/3.305785),0)))) | AC20: =IF($A20="","",IF(O20="공실","공실",IF(O20="자가사용","자가사용",IF(L20="","만료일 없음",IF(L20<$C$6,"만료 경과",IF(L20<=EDATE($C$6,12),"12개월 내","12개월 초과")))))) | AD20: =IF(OR($A20="",O20<>"임대중"),"",IF(B20="",IF(H20="","월세 누락",IF(I20="","관리비 누락","OK")),IF(COUNTIFS($B$13:$B$112,B20,$H$13:$H$112,"<>")>1,"금액 중복",IF(COUNTIFS($B$13:$B$112,B20,$H$13:$H$112,"<>")=0,"월세 누락",IF(COUNTIFS($B$13:$B$112,B20,$I$13:$I$112,"<>")=0,"관리비 누락","OK"))))) | AE20: =IF(OR($A20="",C20=""),"",ROUND(C20*IF($G$9="평",3.305785,1),2)) | AF20: =IF(OR($A20="",D20=""),"",ROUND(D20*IF($G$9="평",3.305785,1),2))
A21: 4F | C21: 266.38 | E21: 사무소 | G21: 100000000 | H21: 4000000 | I21: 240000 | O21: 임대중 | Q21: =IF(OR($A21="",C21=""),"",AE21/3.305785) | R21: =IF(OR($A21="",D21=""),"",AF21/3.305785) | S21: =IF(OR($A21="",C21="",D21=""),"",IF(C21>0,D21/C21*100,"")) | T21: =IF(OR($A21="",O21<>"임대중",F21<>"상가",G21=""),"",G21+H21*100) | U21: =IF(T21="","",IF(T21<=$C$7,"○ 전면적용","× 초과 (5%상한 미적용)")) | V21: =IF(OR($A21="",O21<>"임대중"),"",IF(F21="상가",IF(J21="","확인 필요",TEXT(MAX(0,10-($C$6-J21)/365.25),"0.0")&"년"),IF(F21="주택",IF(M21="있음","소진(1회)",IF(M21="없음",IF(L21="","확인 필요",TEXT(EDATE(L21,24),"yyyy-mm")&"까지"),"확인 필요")),"확인 필요"))) | W21: =IF($A21="","",IF(O21="공실","공실",IF(O21="자가사용","자가사용",IF(L21="","만료일 없음",IF(L21<$C$6,"만료 +"&TEXT($C$6-L21,"0")&"일",IF(L21-$C$6<=30,"임박 "&TEXT(L21-$C$6,"0")&"일","유효")))))) | X21: =IF(OR($A21="",O21<>"임대중"),"",IF(H21="",0,H21)+IF(I21="",0,I21)) | Y21: =IF(OR($A21="",O21<>"임대중",H21=""),"",IF(B21="",IF(D21="","",ROUND((H21+IF(I21="",0,I21))/(AF21/3.305785),0)),IF(COUNTIFS($B$13:$B$112,B21,$D$13:$D$112,"")>0,"",ROUND((H21+IF(I21="",0,I21))/(SUMIFS($AF$13:$AF$112,$B$13:$B$112,B21)/3.305785),0)))) | AC21: =IF($A21="","",IF(O21="공실","공실",IF(O21="자가사용","자가사용",IF(L21="","만료일 없음",IF(L21<$C$6,"만료 경과",IF(L21<=EDATE($C$6,12),"12개월 내","12개월 초과")))))) | AD21: =IF(OR($A21="",O21<>"임대중"),"",IF(B21="",IF(H21="","월세 누락",IF(I21="","관리비 누락","OK")),IF(COUNTIFS($B$13:$B$112,B21,$H$13:$H$112,"<>")>1,"금액 중복",IF(COUNTIFS($B$13:$B$112,B21,$H$13:$H$112,"<>")=0,"월세 누락",IF(COUNTIFS($B$13:$B$112,B21,$I$13:$I$112,"<>")=0,"관리비 누락","OK"))))) | AE21: =IF(OR($A21="",C21=""),"",ROUND(C21*IF($G$9="평",3.305785,1),2)) | AF21: =IF(OR($A21="",D21=""),"",ROUND(D21*IF($G$9="평",3.305785,1),2))
A22: 5F-1 | C22: 135.74 | E22: 학원 | G22: 50000000 | H22: 2500000 | I22: 120000 | O22: 임대중 | Q22: =IF(OR($A22="",C22=""),"",AE22/3.305785) | R22: =IF(OR($A22="",D22=""),"",AF22/3.305785) | S22: =IF(OR($A22="",C22="",D22=""),"",IF(C22>0,D22/C22*100,"")) | T22: =IF(OR($A22="",O22<>"임대중",F22<>"상가",G22=""),"",G22+H22*100) | U22: =IF(T22="","",IF(T22<=$C$7,"○ 전면적용","× 초과 (5%상한 미적용)")) | V22: =IF(OR($A22="",O22<>"임대중"),"",IF(F22="상가",IF(J22="","확인 필요",TEXT(MAX(0,10-($C$6-J22)/365.25),"0.0")&"년"),IF(F22="주택",IF(M22="있음","소진(1회)",IF(M22="없음",IF(L22="","확인 필요",TEXT(EDATE(L22,24),"yyyy-mm")&"까지"),"확인 필요")),"확인 필요"))) | W22: =IF($A22="","",IF(O22="공실","공실",IF(O22="자가사용","자가사용",IF(L22="","만료일 없음",IF(L22<$C$6,"만료 +"&TEXT($C$6-L22,"0")&"일",IF(L22-$C$6<=30,"임박 "&TEXT(L22-$C$6,"0")&"일","유효")))))) | X22: =IF(OR($A22="",O22<>"임대중"),"",IF(H22="",0,H22)+IF(I22="",0,I22)) | Y22: =IF(OR($A22="",O22<>"임대중",H22=""),"",IF(B22="",IF(D22="","",ROUND((H22+IF(I22="",0,I22))/(AF22/3.305785),0)),IF(COUNTIFS($B$13:$B$112,B22,$D$13:$D$112,"")>0,"",ROUND((H22+IF(I22="",0,I22))/(SUMIFS($AF$13:$AF$112,$B$13:$B$112,B22)/3.305785),0)))) | AC22: =IF($A22="","",IF(O22="공실","공실",IF(O22="자가사용","자가사용",IF(L22="","만료일 없음",IF(L22<$C$6,"만료 경과",IF(L22<=EDATE($C$6,12),"12개월 내","12개월 초과")))))) | AD22: =IF(OR($A22="",O22<>"임대중"),"",IF(B22="",IF(H22="","월세 누락",IF(I22="","관리비 누락","OK")),IF(COUNTIFS($B$13:$B$112,B22,$H$13:$H$112,"<>")>1,"금액 중복",IF(COUNTIFS($B$13:$B$112,B22,$H$13:$H$112,"<>")=0,"월세 누락",IF(COUNTIFS($B$13:$B$112,B22,$I$13:$I$112,"<>")=0,"관리비 누락","OK"))))) | AE22: =IF(OR($A22="",C22=""),"",ROUND(C22*IF($G$9="평",3.305785,1),2)) | AF22: =IF(OR($A22="",D22=""),"",ROUND(D22*IF($G$9="평",3.305785,1),2))
A23: 5F-2 | C23: 130.64 | E23: 학원 | G23: 50000000 | H23: 2400000 | I23: 120000 | O23: 임대중 | Q23: =IF(OR($A23="",C23=""),"",AE23/3.305785) | R23: =IF(OR($A23="",D23=""),"",AF23/3.305785) | S23: =IF(OR($A23="",C23="",D23=""),"",IF(C23>0,D23/C23*100,"")) | T23: =IF(OR($A23="",O23<>"임대중",F23<>"상가",G23=""),"",G23+H23*100) | U23: =IF(T23="","",IF(T23<=$C$7,"○ 전면적용","× 초과 (5%상한 미적용)")) | V23: =IF(OR($A23="",O23<>"임대중"),"",IF(F23="상가",IF(J23="","확인 필요",TEXT(MAX(0,10-($C$6-J23)/365.25),"0.0")&"년"),IF(F23="주택",IF(M23="있음","소진(1회)",IF(M23="없음",IF(L23="","확인 필요",TEXT(EDATE(L23,24),"yyyy-mm")&"까지"),"확인 필요")),"확인 필요"))) | W23: =IF($A23="","",IF(O23="공실","공실",IF(O23="자가사용","자가사용",IF(L23="","만료일 없음",IF(L23<$C$6,"만료 +"&TEXT($C$6-L23,"0")&"일",IF(L23-$C$6<=30,"임박 "&TEXT(L23-$C$6,"0")&"일","유효")))))) | X23: =IF(OR($A23="",O23<>"임대중"),"",IF(H23="",0,H23)+IF(I23="",0,I23)) | Y23: =IF(OR($A23="",O23<>"임대중",H23=""),"",IF(B23="",IF(D23="","",ROUND((H23+IF(I23="",0,I23))/(AF23/3.305785),0)),IF(COUNTIFS($B$13:$B$112,B23,$D$13:$D$112,"")>0,"",ROUND((H23+IF(I23="",0,I23))/(SUMIFS($AF$13:$AF$112,$B$13:$B$112,B23)/3.305785),0)))) | AC23: =IF($A23="","",IF(O23="공실","공실",IF(O23="자가사용","자가사용",IF(L23="","만료일 없음",IF(L23<$C$6,"만료 경과",IF(L23<=EDATE($C$6,12),"12개월 내","12개월 초과")))))) | AD23: =IF(OR($A23="",O23<>"임대중"),"",IF(B23="",IF(H23="","월세 누락",IF(I23="","관리비 누락","OK")),IF(COUNTIFS($B$13:$B$112,B23,$H$13:$H$112,"<>")>1,"금액 중복",IF(COUNTIFS($B$13:$B$112,B23,$H$13:$H$112,"<>")=0,"월세 누락",IF(COUNTIFS($B$13:$B$112,B23,$I$13:$I$112,"<>")=0,"관리비 누락","OK"))))) | AE23: =IF(OR($A23="",C23=""),"",ROUND(C23*IF($G$9="평",3.305785,1),2)) | AF23: =IF(OR($A23="",D23=""),"",ROUND(D23*IF($G$9="평",3.305785,1),2))
Q24: =IF(OR($A24="",C24=""),"",AE24/3.305785) | R24: =IF(OR($A24="",D24=""),"",AF24/3.305785) | S24: =IF(OR($A24="",C24="",D24=""),"",IF(C24>0,D24/C24*100,"")) | T24: =IF(OR($A24="",O24<>"임대중",F24<>"상가",G24=""),"",G24+H24*100) | U24: =IF(T24="","",IF(T24<=$C$7,"○ 전면적용","× 초과 (5%상한 미적용)")) | V24: =IF(OR($A24="",O24<>"임대중"),"",IF(F24="상가",IF(J24="","확인 필요",TEXT(MAX(0,10-($C$6-J24)/365.25),"0.0")&"년"),IF(F24="주택",IF(M24="있음","소진(1회)",IF(M24="없음",IF(L24="","확인 필요",TEXT(EDATE(L24,24),"yyyy-mm")&"까지"),"확인 필요")),"확인 필요"))) | W24: =IF($A24="","",IF(O24="공실","공실",IF(O24="자가사용","자가사용",IF(L24="","만료일 없음",IF(L24<$C$6,"만료 +"&TEXT($C$6-L24,"0")&"일",IF(L24-$C$6<=30,"임박 "&TEXT(L24-$C$6,"0")&"일","유효")))))) | X24: =IF(OR($A24="",O24<>"임대중"),"",IF(H24="",0,H24)+IF(I24="",0,I24)) | Y24: =IF(OR($A24="",O24<>"임대중",H24=""),"",IF(B24="",IF(D24="","",ROUND((H24+IF(I24="",0,I24))/(AF24/3.305785),0)),IF(COUNTIFS($B$13:$B$112,B24,$D$13:$D$112,"")>0,"",ROUND((H24+IF(I24="",0,I24))/(SUMIFS($AF$13:$AF$112,$B$13:$B$112,B24)/3.305785),0)))) | AC24: =IF($A24="","",IF(O24="공실","공실",IF(O24="자가사용","자가사용",IF(L24="","만료일 없음",IF(L24<$C$6,"만료 경과",IF(L24<=EDATE($C$6,12),"12개월 내","12개월 초과")))))) | AD24: =IF(OR($A24="",O24<>"임대중"),"",IF(B24="",IF(H24="","월세 누락",IF(I24="","관리비 누락","OK")),IF(COUNTIFS($B$13:$B$112,B24,$H$13:$H$112,"<>")>1,"금액 중복",IF(COUNTIFS($B$13:$B$112,B24,$H$13:$H$112,"<>")=0,"월세 누락",IF(COUNTIFS($B$13:$B$112,B24,$I$13:$I$112,"<>")=0,"관리비 누락","OK"))))) | AE24: =IF(OR($A24="",C24=""),"",ROUND(C24*IF($G$9="평",3.305785,1),2)) | AF24: =IF(OR($A24="",D24=""),"",ROUND(D24*IF($G$9="평",3.305785,1),2))
Q25: =IF(OR($A25="",C25=""),"",AE25/3.305785) | R25: =IF(OR($A25="",D25=""),"",AF25/3.305785) | S25: =IF(OR($A25="",C25="",D25=""),"",IF(C25>0,D25/C25*100,"")) | T25: =IF(OR($A25="",O25<>"임대중",F25<>"상가",G25=""),"",G25+H25*100) | U25: =IF(T25="","",IF(T25<=$C$7,"○ 전면적용","× 초과 (5%상한 미적용)")) | V25: =IF(OR($A25="",O25<>"임대중"),"",IF(F25="상가",IF(J25="","확인 필요",TEXT(MAX(0,10-($C$6-J25)/365.25),"0.0")&"년"),IF(F25="주택",IF(M25="있음","소진(1회)",IF(M25="없음",IF(L25="","확인 필요",TEXT(EDATE(L25,24),"yyyy-mm")&"까지"),"확인 필요")),"확인 필요"))) | W25: =IF($A25="","",IF(O25="공실","공실",IF(O25="자가사용","자가사용",IF(L25="","만료일 없음",IF(L25<$C$6,"만료 +"&TEXT($C$6-L25,"0")&"일",IF(L25-$C$6<=30,"임박 "&TEXT(L25-$C$6,"0")&"일","유효")))))) | X25: =IF(OR($A25="",O25<>"임대중"),"",IF(H25="",0,H25)+IF(I25="",0,I25)) | Y25: =IF(OR($A25="",O25<>"임대중",H25=""),"",IF(B25="",IF(D25="","",ROUND((H25+IF(I25="",0,I25))/(AF25/3.305785),0)),IF(COUNTIFS($B$13:$B$112,B25,$D$13:$D$112,"")>0,"",ROUND((H25+IF(I25="",0,I25))/(SUMIFS($AF$13:$AF$112,$B$13:$B$112,B25)/3.305785),0)))) | AC25: =IF($A25="","",IF(O25="공실","공실",IF(O25="자가사용","자가사용",IF(L25="","만료일 없음",IF(L25<$C$6,"만료 경과",IF(L25<=EDATE($C$6,12),"12개월 내","12개월 초과")))))) | AD25: =IF(OR($A25="",O25<>"임대중"),"",IF(B25="",IF(H25="","월세 누락",IF(I25="","관리비 누락","OK")),IF(COUNTIFS($B$13:$B$112,B25,$H$13:$H$112,"<>")>1,"금액 중복",IF(COUNTIFS($B$13:$B$112,B25,$H$13:$H$112,"<>")=0,"월세 누락",IF(COUNTIFS($B$13:$B$112,B25,$I$13:$I$112,"<>")=0,"관리비 누락","OK"))))) | AE25: =IF(OR($A25="",C25=""),"",ROUND(C25*IF($G$9="평",3.305785,1),2)) | AF25: =IF(OR($A25="",D25=""),"",ROUND(D25*IF($G$9="평",3.305785,1),2))
Q26: =IF(OR($A26="",C26=""),"",AE26/3.305785) | R26: =IF(OR($A26="",D26=""),"",AF26/3.305785) | S26: =IF(OR($A26="",C26="",D26=""),"",IF(C26>0,D26/C26*100,"")) | T26: =IF(OR($A26="",O26<>"임대중",F26<>"상가",G26=""),"",G26+H26*100) | U26: =IF(T26="","",IF(T26<=$C$7,"○ 전면적용","× 초과 (5%상한 미적용)")) | V26: =IF(OR($A26="",O26<>"임대중"),"",IF(F26="상가",IF(J26="","확인 필요",TEXT(MAX(0,10-($C$6-J26)/365.25),"0.0")&"년"),IF(F26="주택",IF(M26="있음","소진(1회)",IF(M26="없음",IF(L26="","확인 필요",TEXT(EDATE(L26,24),"yyyy-mm")&"까지"),"확인 필요")),"확인 필요"))) | W26: =IF($A26="","",IF(O26="공실","공실",IF(O26="자가사용","자가사용",IF(L26="","만료일 없음",IF(L26<$C$6,"만료 +"&TEXT($C$6-L26,"0")&"일",IF(L26-$C$6<=30,"임박 "&TEXT(L26-$C$6,"0")&"일","유효")))))) | X26: =IF(OR($A26="",O26<>"임대중"),"",IF(H26="",0,H26)+IF(I26="",0,I26)) | Y26: =IF(OR($A26="",O26<>"임대중",H26=""),"",IF(B26="",IF(D26="","",ROUND((H26+IF(I26="",0,I26))/(AF26/3.305785),0)),IF(COUNTIFS($B$13:$B$112,B26,$D$13:$D$112,"")>0,"",ROUND((H26+IF(I26="",0,I26))/(SUMIFS($AF$13:$AF$112,$B$13:$B$112,B26)/3.305785),0)))) | AC26: =IF($A26="","",IF(O26="공실","공실",IF(O26="자가사용","자가사용",IF(L26="","만료일 없음",IF(L26<$C$6,"만료 경과",IF(L26<=EDATE($C$6,12),"12개월 내","12개월 초과")))))) | AD26: =IF(OR($A26="",O26<>"임대중"),"",IF(B26="",IF(H26="","월세 누락",IF(I26="","관리비 누락","OK")),IF(COUNTIFS($B$13:$B$112,B26,$H$13:$H$112,"<>")>1,"금액 중복",IF(COUNTIFS($B$13:$B$112,B26,$H$13:$H$112,"<>")=0,"월세 누락",IF(COUNTIFS($B$13:$B$112,B26,$I$13:$I$112,"<>")=0,"관리비 누락","OK"))))) | AE26: =IF(OR($A26="",C26=""),"",ROUND(C26*IF($G$9="평",3.305785,1),2)) | AF26: =IF(OR($A26="",D26=""),"",ROUND(D26*IF($G$9="평",3.305785,1),2))
Q27: =IF(OR($A27="",C27=""),"",AE27/3.305785) | R27: =IF(OR($A27="",D27=""),"",AF27/3.305785) | S27: =IF(OR($A27="",C27="",D27=""),"",IF(C27>0,D27/C27*100,"")) | T27: =IF(OR($A27="",O27<>"임대중",F27<>"상가",G27=""),"",G27+H27*100) | U27: =IF(T27="","",IF(T27<=$C$7,"○ 전면적용","× 초과 (5%상한 미적용)")) | V27: =IF(OR($A27="",O27<>"임대중"),"",IF(F27="상가",IF(J27="","확인 필요",TEXT(MAX(0,10-($C$6-J27)/365.25),"0.0")&"년"),IF(F27="주택",IF(M27="있음","소진(1회)",IF(M27="없음",IF(L27="","확인 필요",TEXT(EDATE(L27,24),"yyyy-mm")&"까지"),"확인 필요")),"확인 필요"))) | W27: =IF($A27="","",IF(O27="공실","공실",IF(O27="자가사용","자가사용",IF(L27="","만료일 없음",IF(L27<$C$6,"만료 +"&TEXT($C$6-L27,"0")&"일",IF(L27-$C$6<=30,"임박 "&TEXT(L27-$C$6,"0")&"일","유효")))))) | X27: =IF(OR($A27="",O27<>"임대중"),"",IF(H27="",0,H27)+IF(I27="",0,I27)) | Y27: =IF(OR($A27="",O27<>"임대중",H27=""),"",IF(B27="",IF(D27="","",ROUND((H27+IF(I27="",0,I27))/(AF27/3.305785),0)),IF(COUNTIFS($B$13:$B$112,B27,$D$13:$D$112,"")>0,"",ROUND((H27+IF(I27="",0,I27))/(SUMIFS($AF$13:$AF$112,$B$13:$B$112,B27)/3.305785),0)))) | AC27: =IF($A27="","",IF(O27="공실","공실",IF(O27="자가사용","자가사용",IF(L27="","만료일 없음",IF(L27<$C$6,"만료 경과",IF(L27<=EDATE($C$6,12),"12개월 내","12개월 초과")))))) | AD27: =IF(OR($A27="",O27<>"임대중"),"",IF(B27="",IF(H27="","월세 누락",IF(I27="","관리비 누락","OK")),IF(COUNTIFS($B$13:$B$112,B27,$H$13:$H$112,"<>")>1,"금액 중복",IF(COUNTIFS($B$13:$B$112,B27,$H$13:$H$112,"<>")=0,"월세 누락",IF(COUNTIFS($B$13:$B$112,B27,$I$13:$I$112,"<>")=0,"관리비 누락","OK"))))) | AE27: =IF(OR($A27="",C27=""),"",ROUND(C27*IF($G$9="평",3.305785,1),2)) | AF27: =IF(OR($A27="",D27=""),"",ROUND(D27*IF($G$9="평",3.305785,1),2))
Q28: =IF(OR($A28="",C28=""),"",AE28/3.305785) | R28: =IF(OR($A28="",D28=""),"",AF28/3.305785) | S28: =IF(OR($A28="",C28="",D28=""),"",IF(C28>0,D28/C28*100,"")) | T28: =IF(OR($A28="",O28<>"임대중",F28<>"상가",G28=""),"",G28+H28*100) | U28: =IF(T28="","",IF(T28<=$C$7,"○ 전면적용","× 초과 (5%상한 미적용)")) | V28: =IF(OR($A28="",O28<>"임대중"),"",IF(F28="상가",IF(J28="","확인 필요",TEXT(MAX(0,10-($C$6-J28)/365.25),"0.0")&"년"),IF(F28="주택",IF(M28="있음","소진(1회)",IF(M28="없음",IF(L28="","확인 필요",TEXT(EDATE(L28,24),"yyyy-mm")&"까지"),"확인 필요")),"확인 필요"))) | W28: =IF($A28="","",IF(O28="공실","공실",IF(O28="자가사용","자가사용",IF(L28="","만료일 없음",IF(L28<$C$6,"만료 +"&TEXT($C$6-L28,"0")&"일",IF(L28-$C$6<=30,"임박 "&TEXT(L28-$C$6,"0")&"일","유효")))))) | X28: =IF(OR($A28="",O28<>"임대중"),"",IF(H28="",0,H28)+IF(I28="",0,I28)) | Y28: =IF(OR($A28="",O28<>"임대중",H28=""),"",IF(B28="",IF(D28="","",ROUND((H28+IF(I28="",0,I28))/(AF28/3.305785),0)),IF(COUNTIFS($B$13:$B$112,B28,$D$13:$D$112,"")>0,"",ROUND((H28+IF(I28="",0,I28))/(SUMIFS($AF$13:$AF$112,$B$13:$B$112,B28)/3.305785),0)))) | AC28: =IF($A28="","",IF(O28="공실","공실",IF(O28="자가사용","자가사용",IF(L28="","만료일 없음",IF(L28<$C$6,"만료 경과",IF(L28<=EDATE($C$6,12),"12개월 내","12개월 초과")))))) | AD28: =IF(OR($A28="",O28<>"임대중"),"",IF(B28="",IF(H28="","월세 누락",IF(I28="","관리비 누락","OK")),IF(COUNTIFS($B$13:$B$112,B28,$H$13:$H$112,"<>")>1,"금액 중복",IF(COUNTIFS($B$13:$B$112,B28,$H$13:$H$112,"<>")=0,"월세 누락",IF(COUNTIFS($B$13:$B$112,B28,$I$13:$I$112,"<>")=0,"관리비 누락","OK"))))) | AE28: =IF(OR($A28="",C28=""),"",ROUND(C28*IF($G$9="평",3.305785,1),2)) | AF28: =IF(OR($A28="",D28=""),"",ROUND(D28*IF($G$9="평",3.305785,1),2))
Q29: =IF(OR($A29="",C29=""),"",AE29/3.305785) | R29: =IF(OR($A29="",D29=""),"",AF29/3.305785) | S29: =IF(OR($A29="",C29="",D29=""),"",IF(C29>0,D29/C29*100,"")) | T29: =IF(OR($A29="",O29<>"임대중",F29<>"상가",G29=""),"",G29+H29*100) | U29: =IF(T29="","",IF(T29<=$C$7,"○ 전면적용","× 초과 (5%상한 미적용)")) | V29: =IF(OR($A29="",O29<>"임대중"),"",IF(F29="상가",IF(J29="","확인 필요",TEXT(MAX(0,10-($C$6-J29)/365.25),"0.0")&"년"),IF(F29="주택",IF(M29="있음","소진(1회)",IF(M29="없음",IF(L29="","확인 필요",TEXT(EDATE(L29,24),"yyyy-mm")&"까지"),"확인 필요")),"확인 필요"))) | W29: =IF($A29="","",IF(O29="공실","공실",IF(O29="자가사용","자가사용",IF(L29="","만료일 없음",IF(L29<$C$6,"만료 +"&TEXT($C$6-L29,"0")&"일",IF(L29-$C$6<=30,"임박 "&TEXT(L29-$C$6,"0")&"일","유효")))))) | X29: =IF(OR($A29="",O29<>"임대중"),"",IF(H29="",0,H29)+IF(I29="",0,I29)) | Y29: =IF(OR($A29="",O29<>"임대중",H29=""),"",IF(B29="",IF(D29="","",ROUND((H29+IF(I29="",0,I29))/(AF29/3.305785),0)),IF(COUNTIFS($B$13:$B$112,B29,$D$13:$D$112,"")>0,"",ROUND((H29+IF(I29="",0,I29))/(SUMIFS($AF$13:$AF$112,$B$13:$B$112,B29)/3.305785),0)))) | AC29: =IF($A29="","",IF(O29="공실","공실",IF(O29="자가사용","자가사용",IF(L29="","만료일 없음",IF(L29<$C$6,"만료 경과",IF(L29<=EDATE($C$6,12),"12개월 내","12개월 초과")))))) | AD29: =IF(OR($A29="",O29<>"임대중"),"",IF(B29="",IF(H29="","월세 누락",IF(I29="","관리비 누락","OK")),IF(COUNTIFS($B$13:$B$112,B29,$H$13:$H$112,"<>")>1,"금액 중복",IF(COUNTIFS($B$13:$B$112,B29,$H$13:$H$112,"<>")=0,"월세 누락",IF(COUNTIFS($B$13:$B$112,B29,$I$13:$I$112,"<>")=0,"관리비 누락","OK"))))) | AE29: =IF(OR($A29="",C29=""),"",ROUND(C29*IF($G$9="평",3.305785,1),2)) | AF29: =IF(OR($A29="",D29=""),"",ROUND(D29*IF($G$9="평",3.305785,1),2))
Q30: =IF(OR($A30="",C30=""),"",AE30/3.305785) | R30: =IF(OR($A30="",D30=""),"",AF30/3.305785) | S30: =IF(OR($A30="",C30="",D30=""),"",IF(C30>0,D30/C30*100,"")) | T30: =IF(OR($A30="",O30<>"임대중",F30<>"상가",G30=""),"",G30+H30*100) | U30: =IF(T30="","",IF(T30<=$C$7,"○ 전면적용","× 초과 (5%상한 미적용)")) | V30: =IF(OR($A30="",O30<>"임대중"),"",IF(F30="상가",IF(J30="","확인 필요",TEXT(MAX(0,10-($C$6-J30)/365.25),"0.0")&"년"),IF(F30="주택",IF(M30="있음","소진(1회)",IF(M30="없음",IF(L30="","확인 필요",TEXT(EDATE(L30,24),"yyyy-mm")&"까지"),"확인 필요")),"확인 필요"))) | W30: =IF($A30="","",IF(O30="공실","공실",IF(O30="자가사용","자가사용",IF(L30="","만료일 없음",IF(L30<$C$6,"만료 +"&TEXT($C$6-L30,"0")&"일",IF(L30-$C$6<=30,"임박 "&TEXT(L30-$C$6,"0")&"일","유효")))))) | X30: =IF(OR($A30="",O30<>"임대중"),"",IF(H30="",0,H30)+IF(I30="",0,I30)) | Y30: =IF(OR($A30="",O30<>"임대중",H30=""),"",IF(B30="",IF(D30="","",ROUND((H30+IF(I30="",0,I30))/(AF30/3.305785),0)),IF(COUNTIFS($B$13:$B$112,B30,$D$13:$D$112,"")>0,"",ROUND((H30+IF(I30="",0,I30))/(SUMIFS($AF$13:$AF$112,$B$13:$B$112,B30)/3.305785),0)))) | AC30: =IF($A30="","",IF(O30="공실","공실",IF(O30="자가사용","자가사용",IF(L30="","만료일 없음",IF(L30<$C$6,"만료 경과",IF(L30<=EDATE($C$6,12),"12개월 내","12개월 초과")))))) | AD30: =IF(OR($A30="",O30<>"임대중"),"",IF(B30="",IF(H30="","월세 누락",IF(I30="","관리비 누락","OK")),IF(COUNTIFS($B$13:$B$112,B30,$H$13:$H$112,"<>")>1,"금액 중복",IF(COUNTIFS($B$13:$B$112,B30,$H$13:$H$112,"<>")=0,"월세 누락",IF(COUNTIFS($B$13:$B$112,B30,$I$13:$I$112,"<>")=0,"관리비 누락","OK"))))) | AE30: =IF(OR($A30="",C30=""),"",ROUND(C30*IF($G$9="평",3.305785,1),2)) | AF30: =IF(OR($A30="",D30=""),"",ROUND(D30*IF($G$9="평",3.305785,1),2))
Q31: =IF(OR($A31="",C31=""),"",AE31/3.305785) | R31: =IF(OR($A31="",D31=""),"",AF31/3.305785) | S31: =IF(OR($A31="",C31="",D31=""),"",IF(C31>0,D31/C31*100,"")) | T31: =IF(OR($A31="",O31<>"임대중",F31<>"상가",G31=""),"",G31+H31*100) | U31: =IF(T31="","",IF(T31<=$C$7,"○ 전면적용","× 초과 (5%상한 미적용)")) | V31: =IF(OR($A31="",O31<>"임대중"),"",IF(F31="상가",IF(J31="","확인 필요",TEXT(MAX(0,10-($C$6-J31)/365.25),"0.0")&"년"),IF(F31="주택",IF(M31="있음","소진(1회)",IF(M31="없음",IF(L31="","확인 필요",TEXT(EDATE(L31,24),"yyyy-mm")&"까지"),"확인 필요")),"확인 필요"))) | W31: =IF($A31="","",IF(O31="공실","공실",IF(O31="자가사용","자가사용",IF(L31="","만료일 없음",IF(L31<$C$6,"만료 +"&TEXT($C$6-L31,"0")&"일",IF(L31-$C$6<=30,"임박 "&TEXT(L31-$C$6,"0")&"일","유효")))))) | X31: =IF(OR($A31="",O31<>"임대중"),"",IF(H31="",0,H31)+IF(I31="",0,I31)) | Y31: =IF(OR($A31="",O31<>"임대중",H31=""),"",IF(B31="",IF(D31="","",ROUND((H31+IF(I31="",0,I31))/(AF31/3.305785),0)),IF(COUNTIFS($B$13:$B$112,B31,$D$13:$D$112,"")>0,"",ROUND((H31+IF(I31="",0,I31))/(SUMIFS($AF$13:$AF$112,$B$13:$B$112,B31)/3.305785),0)))) | AC31: =IF($A31="","",IF(O31="공실","공실",IF(O31="자가사용","자가사용",IF(L31="","만료일 없음",IF(L31<$C$6,"만료 경과",IF(L31<=EDATE($C$6,12),"12개월 내","12개월 초과")))))) | AD31: =IF(OR($A31="",O31<>"임대중"),"",IF(B31="",IF(H31="","월세 누락",IF(I31="","관리비 누락","OK")),IF(COUNTIFS($B$13:$B$112,B31,$H$13:$H$112,"<>")>1,"금액 중복",IF(COUNTIFS($B$13:$B$112,B31,$H$13:$H$112,"<>")=0,"월세 누락",IF(COUNTIFS($B$13:$B$112,B31,$I$13:$I$112,"<>")=0,"관리비 누락","OK"))))) | AE31: =IF(OR($A31="",C31=""),"",ROUND(C31*IF($G$9="평",3.305785,1),2)) | AF31: =IF(OR($A31="",D31=""),"",ROUND(D31*IF($G$9="평",3.305785,1),2))
Q32: =IF(OR($A32="",C32=""),"",AE32/3.305785) | R32: =IF(OR($A32="",D32=""),"",AF32/3.305785) | S32: =IF(OR($A32="",C32="",D32=""),"",IF(C32>0,D32/C32*100,"")) | T32: =IF(OR($A32="",O32<>"임대중",F32<>"상가",G32=""),"",G32+H32*100) | U32: =IF(T32="","",IF(T32<=$C$7,"○ 전면적용","× 초과 (5%상한 미적용)")) | V32: =IF(OR($A32="",O32<>"임대중"),"",IF(F32="상가",IF(J32="","확인 필요",TEXT(MAX(0,10-($C$6-J32)/365.25),"0.0")&"년"),IF(F32="주택",IF(M32="있음","소진(1회)",IF(M32="없음",IF(L32="","확인 필요",TEXT(EDATE(L32,24),"yyyy-mm")&"까지"),"확인 필요")),"확인 필요"))) | W32: =IF($A32="","",IF(O32="공실","공실",IF(O32="자가사용","자가사용",IF(L32="","만료일 없음",IF(L32<$C$6,"만료 +"&TEXT($C$6-L32,"0")&"일",IF(L32-$C$6<=30,"임박 "&TEXT(L32-$C$6,"0")&"일","유효")))))) | X32: =IF(OR($A32="",O32<>"임대중"),"",IF(H32="",0,H32)+IF(I32="",0,I32)) | Y32: =IF(OR($A32="",O32<>"임대중",H32=""),"",IF(B32="",IF(D32="","",ROUND((H32+IF(I32="",0,I32))/(AF32/3.305785),0)),IF(COUNTIFS($B$13:$B$112,B32,$D$13:$D$112,"")>0,"",ROUND((H32+IF(I32="",0,I32))/(SUMIFS($AF$13:$AF$112,$B$13:$B$112,B32)/3.305785),0)))) | AC32: =IF($A32="","",IF(O32="공실","공실",IF(O32="자가사용","자가사용",IF(L32="","만료일 없음",IF(L32<$C$6,"만료 경과",IF(L32<=EDATE($C$6,12),"12개월 내","12개월 초과")))))) | AD32: =IF(OR($A32="",O32<>"임대중"),"",IF(B32="",IF(H32="","월세 누락",IF(I32="","관리비 누락","OK")),IF(COUNTIFS($B$13:$B$112,B32,$H$13:$H$112,"<>")>1,"금액 중복",IF(COUNTIFS($B$13:$B$112,B32,$H$13:$H$112,"<>")=0,"월세 누락",IF(COUNTIFS($B$13:$B$112,B32,$I$13:$I$112,"<>")=0,"관리비 누락","OK"))))) | AE32: =IF(OR($A32="",C32=""),"",ROUND(C32*IF($G$9="평",3.305785,1),2)) | AF32: =IF(OR($A32="",D32=""),"",ROUND(D32*IF($G$9="평",3.305785,1),2))
Q33: =IF(OR($A33="",C33=""),"",AE33/3.305785) | R33: =IF(OR($A33="",D33=""),"",AF33/3.305785) | S33: =IF(OR($A33="",C33="",D33=""),"",IF(C33>0,D33/C33*100,"")) | T33: =IF(OR($A33="",O33<>"임대중",F33<>"상가",G33=""),"",G33+H33*100) | U33: =IF(T33="","",IF(T33<=$C$7,"○ 전면적용","× 초과 (5%상한 미적용)")) | V33: =IF(OR($A33="",O33<>"임대중"),"",IF(F33="상가",IF(J33="","확인 필요",TEXT(MAX(0,10-($C$6-J33)/365.25),"0.0")&"년"),IF(F33="주택",IF(M33="있음","소진(1회)",IF(M33="없음",IF(L33="","확인 필요",TEXT(EDATE(L33,24),"yyyy-mm")&"까지"),"확인 필요")),"확인 필요"))) | W33: =IF($A33="","",IF(O33="공실","공실",IF(O33="자가사용","자가사용",IF(L33="","만료일 없음",IF(L33<$C$6,"만료 +"&TEXT($C$6-L33,"0")&"일",IF(L33-$C$6<=30,"임박 "&TEXT(L33-$C$6,"0")&"일","유효")))))) | X33: =IF(OR($A33="",O33<>"임대중"),"",IF(H33="",0,H33)+IF(I33="",0,I33)) | Y33: =IF(OR($A33="",O33<>"임대중",H33=""),"",IF(B33="",IF(D33="","",ROUND((H33+IF(I33="",0,I33))/(AF33/3.305785),0)),IF(COUNTIFS($B$13:$B$112,B33,$D$13:$D$112,"")>0,"",ROUND((H33+IF(I33="",0,I33))/(SUMIFS($AF$13:$AF$112,$B$13:$B$112,B33)/3.305785),0)))) | AC33: =IF($A33="","",IF(O33="공실","공실",IF(O33="자가사용","자가사용",IF(L33="","만료일 없음",IF(L33<$C$6,"만료 경과",IF(L33<=EDATE($C$6,12),"12개월 내","12개월 초과")))))) | AD33: =IF(OR($A33="",O33<>"임대중"),"",IF(B33="",IF(H33="","월세 누락",IF(I33="","관리비 누락","OK")),IF(COUNTIFS($B$13:$B$112,B33,$H$13:$H$112,"<>")>1,"금액 중복",IF(COUNTIFS($B$13:$B$112,B33,$H$13:$H$112,"<>")=0,"월세 누락",IF(COUNTIFS($B$13:$B$112,B33,$I$13:$I$112,"<>")=0,"관리비 누락","OK"))))) | AE33: =IF(OR($A33="",C33=""),"",ROUND(C33*IF($G$9="평",3.305785,1),2)) | AF33: =IF(OR($A33="",D33=""),"",ROUND(D33*IF($G$9="평",3.305785,1),2))
Q34: =IF(OR($A34="",C34=""),"",AE34/3.305785) | R34: =IF(OR($A34="",D34=""),"",AF34/3.305785) | S34: =IF(OR($A34="",C34="",D34=""),"",IF(C34>0,D34/C34*100,"")) | T34: =IF(OR($A34="",O34<>"임대중",F34<>"상가",G34=""),"",G34+H34*100) | U34: =IF(T34="","",IF(T34<=$C$7,"○ 전면적용","× 초과 (5%상한 미적용)")) | V34: =IF(OR($A34="",O34<>"임대중"),"",IF(F34="상가",IF(J34="","확인 필요",TEXT(MAX(0,10-($C$6-J34)/365.25),"0.0")&"년"),IF(F34="주택",IF(M34="있음","소진(1회)",IF(M34="없음",IF(L34="","확인 필요",TEXT(EDATE(L34,24),"yyyy-mm")&"까지"),"확인 필요")),"확인 필요"))) | W34: =IF($A34="","",IF(O34="공실","공실",IF(O34="자가사용","자가사용",IF(L34="","만료일 없음",IF(L34<$C$6,"만료 +"&TEXT($C$6-L34,"0")&"일",IF(L34-$C$6<=30,"임박 "&TEXT(L34-$C$6,"0")&"일","유효")))))) | X34: =IF(OR($A34="",O34<>"임대중"),"",IF(H34="",0,H34)+IF(I34="",0,I34)) | Y34: =IF(OR($A34="",O34<>"임대중",H34=""),"",IF(B34="",IF(D34="","",ROUND((H34+IF(I34="",0,I34))/(AF34/3.305785),0)),IF(COUNTIFS($B$13:$B$112,B34,$D$13:$D$112,"")>0,"",ROUND((H34+IF(I34="",0,I34))/(SUMIFS($AF$13:$AF$112,$B$13:$B$112,B34)/3.305785),0)))) | AC34: =IF($A34="","",IF(O34="공실","공실",IF(O34="자가사용","자가사용",IF(L34="","만료일 없음",IF(L34<$C$6,"만료 경과",IF(L34<=EDATE($C$6,12),"12개월 내","12개월 초과")))))) | AD34: =IF(OR($A34="",O34<>"임대중"),"",IF(B34="",IF(H34="","월세 누락",IF(I34="","관리비 누락","OK")),IF(COUNTIFS($B$13:$B$112,B34,$H$13:$H$112,"<>")>1,"금액 중복",IF(COUNTIFS($B$13:$B$112,B34,$H$13:$H$112,"<>")=0,"월세 누락",IF(COUNTIFS($B$13:$B$112,B34,$I$13:$I$112,"<>")=0,"관리비 누락","OK"))))) | AE34: =IF(OR($A34="",C34=""),"",ROUND(C34*IF($G$9="평",3.305785,1),2)) | AF34: =IF(OR($A34="",D34=""),"",ROUND(D34*IF($G$9="평",3.305785,1),2))
Q35: =IF(OR($A35="",C35=""),"",AE35/3.305785) | R35: =IF(OR($A35="",D35=""),"",AF35/3.305785) | S35: =IF(OR($A35="",C35="",D35=""),"",IF(C35>0,D35/C35*100,"")) | T35: =IF(OR($A35="",O35<>"임대중",F35<>"상가",G35=""),"",G35+H35*100) | U35: =IF(T35="","",IF(T35<=$C$7,"○ 전면적용","× 초과 (5%상한 미적용)")) | V35: =IF(OR($A35="",O35<>"임대중"),"",IF(F35="상가",IF(J35="","확인 필요",TEXT(MAX(0,10-($C$6-J35)/365.25),"0.0")&"년"),IF(F35="주택",IF(M35="있음","소진(1회)",IF(M35="없음",IF(L35="","확인 필요",TEXT(EDATE(L35,24),"yyyy-mm")&"까지"),"확인 필요")),"확인 필요"))) | W35: =IF($A35="","",IF(O35="공실","공실",IF(O35="자가사용","자가사용",IF(L35="","만료일 없음",IF(L35<$C$6,"만료 +"&TEXT($C$6-L35,"0")&"일",IF(L35-$C$6<=30,"임박 "&TEXT(L35-$C$6,"0")&"일","유효")))))) | X35: =IF(OR($A35="",O35<>"임대중"),"",IF(H35="",0,H35)+IF(I35="",0,I35)) | Y35: =IF(OR($A35="",O35<>"임대중",H35=""),"",IF(B35="",IF(D35="","",ROUND((H35+IF(I35="",0,I35))/(AF35/3.305785),0)),IF(COUNTIFS($B$13:$B$112,B35,$D$13:$D$112,"")>0,"",ROUND((H35+IF(I35="",0,I35))/(SUMIFS($AF$13:$AF$112,$B$13:$B$112,B35)/3.305785),0)))) | AC35: =IF($A35="","",IF(O35="공실","공실",IF(O35="자가사용","자가사용",IF(L35="","만료일 없음",IF(L35<$C$6,"만료 경과",IF(L35<=EDATE($C$6,12),"12개월 내","12개월 초과")))))) | AD35: =IF(OR($A35="",O35<>"임대중"),"",IF(B35="",IF(H35="","월세 누락",IF(I35="","관리비 누락","OK")),IF(COUNTIFS($B$13:$B$112,B35,$H$13:$H$112,"<>")>1,"금액 중복",IF(COUNTIFS($B$13:$B$112,B35,$H$13:$H$112,"<>")=0,"월세 누락",IF(COUNTIFS($B$13:$B$112,B35,$I$13:$I$112,"<>")=0,"관리비 누락","OK"))))) | AE35: =IF(OR($A35="",C35=""),"",ROUND(C35*IF($G$9="평",3.305785,1),2)) | AF35: =IF(OR($A35="",D35=""),"",ROUND(D35*IF($G$9="평",3.305785,1),2))
... Q112: =IF(OR($A112="",C112=""),"",AE112/3.305785) | R112: =IF(OR($A112="",D112=""),"",AF112/3.305785) | S112: =IF(OR($A112="",C112="",D112=""),"",IF(C112>0,D112/C112*100,"")) | T112: =IF(OR($A112="",O112<>"임대중",F112<>"상가",G112=""),"",G112+H112*100) | U112: =IF(T112="","",IF(T112<=$C$7,"○ 전면적용","× 초과 (5%상한 미적용)")) | V112: =IF(OR($A112="",O112<>"임대중"),"",IF(F112="상가",IF(J112="","확인 필요",TEXT(MAX(0,10-($C$6-J112)/365.25),"0.0")&"년"),IF(F112="주택",IF(M112="있음","소진(1회)",IF(M112="없음",IF(L112="","확인 필요",TEXT(EDATE(L112,24),"yyyy-mm")&"까지"),"확인 필요")),"확인 필요"))) | W112: =IF($A112="","",IF(O112="공실","공실",IF(O112="자가사용","자가사용",IF(L112="","만료일 없음",IF(L112<$C$6,"만료 +"&TEXT($C$6-L112,"0")&"일",IF(L112-$C$6<=30,"임박 "&TEXT(L112-$C$6,"0")&"일","유효")))))) | X112: =IF(OR($A112="",O112<>"임대중"),"",IF(H112="",0,H112)+IF(I112="",0,I112)) | Y112: =IF(OR($A112="",O112<>"임대중",H112=""),"",IF(B112="",IF(D112="","",ROUND((H112+IF(I112="",0,I112))/(AF112/3.305785),0)),IF(COUNTIFS($B$13:$B$112,B112,$D$13:$D$112,"")>0,"",ROUND((H112+IF(I112="",0,I112))/(SUMIFS($AF$13:$AF$112,$B$13:$B$112,B112)/3.305785),0)))) | AC112: =IF($A112="","",IF(O112="공실","공실",IF(O112="자가사용","자가사용",IF(L112="","만료일 없음",IF(L112<$C$6,"만료 경과",IF(L112<=EDATE($C$6,12),"12개월 내","12개월 초과")))))) | AD112: =IF(OR($A112="",O112<>"임대중"),"",IF(B112="",IF(H112="","월세 누락",IF(I112="","관리비 누락","OK")),IF(COUNTIFS($B$13:$B$112,B112,$H$13:$H$112,"<>")>1,"금액 중복",IF(COUNTIFS($B$13:$B$112,B112,$H$13:$H$112,"<>")=0,"월세 누락",IF(COUNTIFS($B$13:$B$112,B112,$I$13:$I$112,"<>")=0,"관리비 누락","OK"))))) | AE112: =IF(OR($A112="",C112=""),"",ROUND(C112*IF($G$9="평",3.305785,1),2)) | AF112: =IF(OR($A112="",D112=""),"",ROUND(D112*IF($G$9="평",3.305785,1),2))

Sheet 자동검증
A1: 자동 검증 — 발행 전 확인
A3: # | B3: 검증 항목 | C3: 결과 | D3: 판정 기준
A4: G19 | B4: 렌트롤 월세 합계 (정본) | C4: =TEXT(SUM(렌트롤!$H$13:$H$112),"#,##0")&"원" | D4: 표지 요약과 다르면 발행 차단. 이 표가 정본입니다.
A5: C19 | B5: 임대면적 합계 | C5: =TEXT(SUM(렌트롤!$AE$13:$AE$112),"#,##0.00")&"㎡ / "&TEXT(SUM(렌트롤!$Q$13:$Q$112),"#,##0.0")&"평" | D5: 건축물대장 연면적과 대조. 입력 단위와 상관없이 ㎡ 환산값으로 표시합니다.
A6: C19-E | B6: 전용면적 합계 | C6: =TEXT(SUM(렌트롤!$AF$13:$AF$112),"#,##0.00")&"㎡ / "&TEXT(SUM(렌트롤!$R$13:$R$112),"#,##0.0")&"평" | D6: 건축물대장 전유면적 합계와 0.5% 이내 일치해야 합니다 (A01 경고 기준).
A7: C19-R | B7: 가중 전용률 | C7: =IF(렌트롤!$S$10="","산출 불가 (임대·전용면적 쌍 없음)",TEXT(렌트롤!$S$10,"0.0")&"%") | D7: Σ전용면적 ÷ Σ임대면적 (두 면적이 모두 있는 호실만). 호실별 전용률의 단순 평균이 아닙니다.
A8: C19-M | B8: 임대면적 미기재 호실 | C8: =COUNTIFS(렌트롤!$A$13:$A$112,"<>",렌트롤!$C$13:$C$112,"")&"건" | D8: 1건 이상이면 R2 미달 — 평당 단가·면적 공실률 산출 불가.
A9: C19-X | B9: 전용면적 미기재 호실 | C9: =COUNTIFS(렌트롤!$A$13:$A$112,"<>",렌트롤!$D$13:$D$112,"")&"건" | D9: 1건 이상이면 전용률·전용평당 월비용 보류. (공실 호실 포함)
A10: C19-V | B10: 전용률 이상치 | C10: =COUNTIF(렌트롤!$S$13:$S$112,">100")&"건 100% 초과 / "&COUNTIF(렌트롤!$S$13:$S$112,"<30")&"건 30% 미만" | D10: 100% 초과 = 전용면적이 임대면적보다 큰 입력 오류(발행 보류). 30% 미만 = 면적 기재 오류 의심.
A11: F11 | B11: 만료 계약 수 | C11: =COUNTIF(렌트롤!$W$13:$W$112,"만료*")&" / "&COUNTIF(렌트롤!$O$13:$O$112,"임대중")&"건" | D11: 1건 이상이면 호실별 경고.
A12: F12 | B12: 만료 비율 50% 초과 | C12: =IF(COUNTIF(렌트롤!$W$13:$W$112,"만료*")>COUNTIF(렌트롤!$O$13:$O$112,"임대중")/2,"발행 차단","통과") | D12: 절반 초과 시 렌트롤 갱신 전까지 발행 불가.
A13: F13 | B13: 30일 내 만료 임박 | C13: =COUNTIF(렌트롤!$W$13:$W$112,"임박*")&"건" | D13: 재계약 조건이 딜 구조를 바꿉니다. 협의 상태 확인 필요.
A14: G18 | B14: 갱신권 판정 보류 | C14: =COUNTIF(렌트롤!$V$13:$V$112,"확인 필요")&"건" | D14: 최초계약일(상가)·행사이력(주택) 누락. 숫자 대신 "확인 필요" 출력.
A15: G13 | B15: 대항력 미확인 | C15: =COUNTIF(렌트롤!$N$13:$N$112,"미확인")&"건" | D15: 근거 없이 "없음" 표기 시 발행 차단.
A16: G17 | B16: 업종 미기재 | C16: =COUNTIFS(렌트롤!$A$13:$A$112,"<>",렌트롤!$E$13:$E$112,"")&"건" | D16: 비면 "미상"으로 출력. 추론 금지.
A17: T-C | B17: 환산보증금 초과 호실 | C17: =COUNTIF(렌트롤!$U$13:$U$112,"×*")&"건" | D17: 초과 시 5% 인상상한·우선변제권 미적용. 갱신요구권은 적용됨.
A18: F01 | B18: 렌트롤 기준일 | C18: =IF(렌트롤!$C$5="","미기재",TEXT(렌트롤!$C$5,"yyyy-mm-dd")) | D18: 없으면 신선도 판정 불가.
A19: C21 | B19: 공실 / 자가사용 | C19: =COUNTIF(렌트롤!$O$13:$O$112,"공실")&"건 / "&COUNTIF(렌트롤!$O$13:$O$112,"자가사용")&"건" | D19: 자가사용은 임대 전환 여력. 공실 손실과 구분합니다.
A21: 해상도 판정 — 이 렌트롤로 무엇을 만들 수 있나
A22: 등급 | B22: 요건 | C22: 충족 | D22: 열리는 기능
A23: R1 최소형 | B23: 호실·업종·월세·만료일·임대상태 (임대중 호실 전부 — 통합계약은 그룹마다 대표 행 1개에 월세) | C23: =IF(AND(COUNTA(렌트롤!$A$13:$A$112)>0,COUNTA(렌트롤!$O$13:$O$112)=COUNTA(렌트롤!$A$13:$A$112),COUNTIFS(렌트롤!$O$13:$O$112,"임대중",렌트롤!$E$13:$E$112,"<>")=COUNTIF(렌트롤!$O$13:$O$112,"임대중"),COUNTIF(렌트롤!$AD$13:$AD$112,"월세 누락")=0,COUNTIF(렌트롤!$AD$13:$AD$112,"금액 중복")=0,COUNTIFS(렌트롤!$O$13:$O$112,"임대중",렌트롤!$L$13:$L$112,"<>")=COUNTIF(렌트롤!$O$13:$O$112,"임대중")),"충족","미달") | D23: 렌트롤 표 · 만료 타임라인 · 총액 수익률
A24: R2 필요형 | B24: R1 + 임대면적(전 호실)·적용법령(전 호실)·관리비(임대중, 통합계약은 대표 행) | C24: =IF(AND(C23="충족",COUNTA(렌트롤!$C$13:$C$112)=COUNTA(렌트롤!$A$13:$A$112),COUNTA(렌트롤!$F$13:$F$112)=COUNTA(렌트롤!$A$13:$A$112),COUNTIF(렌트롤!$AD$13:$AD$112,"관리비 누락")=0),"충족","미달") | D24: 평당 단가 · 층별 단가 · 환산보증금 · 상임법 판정
A25: R3 표준형 | B25: R2 + 최초계약일·대항력 (임대중 호실 전부 — 통합계약의 비대표 행 포함, '미확인' 불가) | C25: =IF(AND(C24="충족",COUNTIFS(렌트롤!$O$13:$O$112,"임대중",렌트롤!$J$13:$J$112,"<>")=COUNTIF(렌트롤!$O$13:$O$112,"임대중"),COUNTIFS(렌트롤!$O$13:$O$112,"임대중",렌트롤!$N$13:$N$112,"<>")=COUNTIF(렌트롤!$O$13:$O$112,"임대중"),COUNTIFS(렌트롤!$O$13:$O$112,"임대중",렌트롤!$N$13:$N$112,"미확인")=0),"충족","미달") | D25: 갱신요구권 · 명도 계획 · 임대료 정상화 시뮬
A26: 면적 보강 | B26: 전 호실 임대면적·전용면적 입력, 전용률 100% 이하 (등급 무관) | C26: =IF(AND(COUNTA(렌트롤!$A$13:$A$112)>0,COUNTA(렌트롤!$C$13:$C$112)=COUNTA(렌트롤!$A$13:$A$112),COUNTA(렌트롤!$D$13:$D$112)=COUNTA(렌트롤!$A$13:$A$112),COUNTIF(렌트롤!$S$13:$S$112,">100")=0),"충족","미달") | D26: 전용률 · 전용평당 월비용(NOC)
B28: 현재 해상도 | C28: =IF(C25="충족","R3 표준형",IF(C24="충족","R2 필요형",IF(C23="충족","R1 최소형","R0 미달")))
B29: 다음 한 칸 | C29: =IF(C23<>"충족","「업종」「월세」「현 계약 만료일」「임대상태」부터 채우세요. 렌트롤 표를 그릴 수 없습니다",IF(C24<>"충족","「적용법령」「관리비」를 채우면 환산보증금·상임법 판정이 열립니다. 「임대면적」은 평당 단가를 엽니다",IF(C25<>"충족","「최초 계약일」과 「대항력 요건」을 채우면 갱신요구권·명도 계획이 열립니다",IF(C26<>"충족","「전용면적」을 모든 호실에 채우면 전용률·전용평당 월비용이 열립니다","완료 — 모든 기능 사용 가능"))))
B31: ※ 이 시트는 참고용입니다. 시스템은 '렌트롤' 시트를 자동으로 읽습니다.
A33: v1.4 추가 검증 — IM 연계
A34: # | B34: 검증 항목 | C34: 결과 | D34: 판정 기준
A35: V01 | B35: 통합계약 금액 | C35: =COUNTIF(렌트롤!$AD$13:$AD$112,"월세 누락")&"건 월세 누락 / "&COUNTIF(렌트롤!$AD$13:$AD$112,"금액 중복")&"건 그룹 금액 중복" | D35: 그룹마다 대표 행 1개에만 금액. 중복이면 합계·환산보증금이 틀어지므로 발행 차단.
A36: V02 | B36: 평가 기준일 | C36: =IF(렌트롤!$C$5="","⚠ 렌트롤 기준일 없음 — TODAY() 사용 중(재현 불가)","렌트롤 기준일로 고정: "&TEXT(렌트롤!$C$5,"yyyy-mm-dd")) | D36: IM 발행 시 같은 렌트롤이면 같은 숫자가 나와야 합니다.
A37: V03 | B37: 임대면적 합 ÷ 연면적 | C37: =IF(렌트롤!$J$4="","연면적 미입력",TEXT(SUM(렌트롤!$AE$13:$AE$112)/렌트롤!$J$4,"0.0%")) | D37: 주차장·기계실 제외로 100% 미만이 정상. 75% 미만이면 호실 누락, 100% 초과면 면적 오기 의심.
A38: V04 | B38: 단순 수익률 | C38: =IF(OR(렌트롤!$J$3="",렌트롤!$J$3-SUM(렌트롤!$G$13:$G$112)<=0),"매각가 미입력",TEXT(SUM(렌트롤!$H$13:$H$112)*12/(렌트롤!$J$3-SUM(렌트롤!$G$13:$G$112)),"0.00%")) | D38: 연 월세 합계 ÷ (매각가 − 보증금 합계). 관리비·기타수입 제외. IM 전 장의 수익률 정본.
A39: V05 | B39: 수익률 (기타수입 포함) | C39: =IF(OR(렌트롤!$J$3="",렌트롤!$J$3-SUM(렌트롤!$G$13:$G$112)<=0),"매각가 미입력",TEXT((SUM(렌트롤!$H$13:$H$112)+N(렌트롤!$J$8))*12/(렌트롤!$J$3-SUM(렌트롤!$G$13:$G$112)),"0.00%")) | D39: IM에는 기타수입을 별도 줄로 표기.
A40: V06 | B40: 12개월 내 만기 월세 비중 | C40: =IF(SUM(렌트롤!$H$13:$H$112)=0,"-",TEXT((SUMIFS(렌트롤!$H$13:$H$112,렌트롤!$AC$13:$AC$112,"12개월 내")+SUMIFS(렌트롤!$H$13:$H$112,렌트롤!$AC$13:$AC$112,"만료 경과"))/SUM(렌트롤!$H$13:$H$112),"0.0%")) | D40: 만료 경과(묵시 갱신) 포함. 50% 초과면 IM 요약·스태킹 플랜 헤드라인에 반영.
A41: V07 | B41: 근거 분포 (계약 단위) | C41: =COUNTIFS(렌트롤!$O$13:$O$112,"임대중",렌트롤!$Z$13:$Z$112,"계약서 원본",렌트롤!$H$13:$H$112,"<>")&" 원본 / "&COUNTIFS(렌트롤!$O$13:$O$112,"임대중",렌트롤!$Z$13:$Z$112,"매도인 렌트롤",렌트롤!$H$13:$H$112,"<>")&" 매도인 / "&COUNTIFS(렌트롤!$O$13:$O$112,"임대중",렌트롤!$Z$13:$Z$112,"구두",렌트롤!$H$13:$H$112,"<>")&" 구두 / "&COUNTIFS(렌트롤!$O$13:$O$112,"임대중",렌트롤!$Z$13:$Z$112,"",렌트롤!$H$13:$H$112,"<>")&" 미기재" | D41: 월세가 적힌 행(계약 1건) 기준. IM 렌트롤 장 상단 배지와 출처 줄에 그대로 표시. 구두가 있으면 해당 행에 [매도인 구두] 표기.
A42: V08 | B42: 입금 확인 | C42: =COUNTIFS(렌트롤!$AB$13:$AB$112,"연체",렌트롤!$H$13:$H$112,"<>")&"건 연체 / "&(COUNTIFS(렌트롤!$O$13:$O$112,"임대중",렌트롤!$AB$13:$AB$112,"미확인",렌트롤!$H$13:$H$112,"<>")+COUNTIFS(렌트롤!$O$13:$O$112,"임대중",렌트롤!$AB$13:$AB$112,"",렌트롤!$H$13:$H$112,"<>"))&"건 미확인" | D42: 연체가 있으면 유의사항 장으로 이동. 미확인은 "입금 내역 미대조"로 표시.
A43: V09 | B43: 렌트프리 호실 | C43: =COUNTIF(렌트롤!$AA$13:$AA$112,">0")&"건" | D43: 1건 이상이면 수익률 카드에 "렌트프리 반영 전" 표시.
A44: V10 | B44: 시장 임대료 입력 | C44: =COUNT(렌트롤!$J$5:$J$7)&"/3칸, 출처 "&COUNTA(렌트롤!$M$5:$M$7)&"/3칸" | D44: R3 임대료 정상화 시뮬은 해당 층 시장 임대료와 출처가 있어야 열립니다.
A45: V11 | B45: R3+ 고품질 IM 준비 | C45: =IF(AND(C25="충족",COUNT(렌트롤!$J$5:$J$7)>=1,COUNTA(렌트롤!$M$5:$M$7)>=COUNT(렌트롤!$J$5:$J$7),COUNTIFS(렌트롤!$O$13:$O$112,"임대중",렌트롤!$Z$13:$Z$112,"")=0),"충족","미달") | D45: R3 + 시장 임대료(출처 포함) 1칸 이상 + 근거 전 호실 → 갱신권 타임라인·정상화 시뮬·민감도 3장 생성.
...

Sheet 컬럼정의
A1: 컬럼 정의 — R1 / R2 / R3 해상도별 입력 항목과 설명
A2: 해상도 = 이 렌트롤로 만들 수 있는 분석의 깊이. 판정 로직: src/domain/building/mobile-im/lease-math.ts resolveLedger(). R0은 R1 요건 미달.
A3: 열 | B3: 컬럼명 | C3: 해상도 | D3: 필수도 | E3: 입력 방식 · 단위 | F3: 설명 | G3: 업로드 반영 필드 | H3: 도메인 필드 (LeaseRow) | I3: 비었을 때 영향
A4: A | B4: 호실/층 | C4: R1 | D4: 필수 | E4: 텍스트 | F4: 원본 표기 그대로 (예: B1, 1F, 101호). 한 층에 호실이 둘이면 행을 나눠 적습니다. | G4: floor | H4: unitLabel | I4: 행 식별 불가 — 층 라벨이 'N F'로 대체됩니다.
A5: B | B5: 계약그룹 | C5: R2 | D5: 조건부 | E5: 텍스트 | F5: 통합계약 표시. 한 임차인이 한 계약서로 여러 호실·층을 쓸 때, 그 호실들에 같은 이름(A, B, 1…)을 적습니다. 보증금·월세·관리비는 대표 행 한 곳에만 적고 나머지 행은 비웁니다(면적·만료일 등은 행마다 적음). 호실별로 따로 계약했다면 비워 두세요. | G5: contract_group | H5: contractGroup | I5: 통합계약 금액 중복 집계 위험(대표 행 외 금액을 비워 두면 영향 없음). 비우면 호실마다 별개 계약으로 취급됩니다.
A6: C | B6: 임대면적(G9 단위) | C6: R2 | D6: 권장 | E6: ㎡ 또는 평 (G9 선택, 소수 2자리) | F6: 임대차계약서상 계약면적 = 전용면적 + 공용면적 분담분. 임대료 평당 단가·면적 기준 공실률의 분모입니다. 공실·자가사용 호실도 적습니다. | G6: area_sqm (AE열 ㎡ 환산값) | H6: leaseAreaSqm | I6: R2 미달 — 평당 임대단가·면적 공실률·임대료 정상화 산출 불가.
A7: D | B7: 전용면적(G9 단위) | C7: R2* | D7: 권장 | E7: ㎡ 또는 평 (G9 선택, 소수 2자리) | F7: 임차인이 독점해 사용하는 면적(건축물대장 전유부 기준). 임대면적보다 클 수 없습니다. 전용률과 전용평당 월비용의 분모입니다. (* 등급 판정에는 영향 없는 보강 항목) | G7: exclusive_area_sqm (AF열 ㎡ 환산값) | H7: exclusiveAreaSqm | I7: 전용률·전용평당 월비용 보류. IM 렌트롤 표에서 전용면적 열이 빠지고 임대면적만 표기됩니다(다른 면적 값으로 대신 채우지 않음).
A8: E | B8: 업종/상호 (원문) | C8: R1 | D8: 필수 | E8: 텍스트 | F8: 계약서·렌트롤에 적힌 문구를 그대로 옮깁니다. 업종을 추측해 바꾸지 마세요. 공실이면 '공실'. | G8: tenant_type · tenant_name | H8: tenantBusiness | I8: R1 미달 — 렌트롤 표를 그릴 수 없고, 임대상태 미기재 시 공실로 추정됩니다.
A9: F | B9: 적용법령 | C9: R2 | D9: 권장 | E9: 드롭다운 상가/주택/미확인 | F9: 상가 / 주택 / 미확인. 주거로 쓰는 오피스텔은 '주택'. 갱신요구권 산식이 완전히 달라집니다. | G9: legal_basis | H9: legalBasis | I9: R2 미달 — 환산보증금·상임법 판정·갱신권 잔여 '확인 필요'.
A10: G | B10: 보증금(원) | C10: R1 | D10: 필수 | E10: 원 (VAT 별도) | F10: 원 단위 숫자만. '5,000만'처럼 적지 마세요 (5,000만원 → 50000000). | G10: deposit_manwon (÷10,000) | H10: depositKrw | I10: R1 미달 — 보증금 합계·환산보증금 산출 불가.
A11: H | B11: 월세(원,VAT별도) | C11: R1 | D11: 필수 | E11: 원 (VAT 별도) | F11: 월 임대료. VAT·관리비 제외. 원 단위 숫자만. | G11: rent_manwon (÷10,000) | H11: monthlyRentKrw | I11: R1 미달 — 임대수입·수익률(Gross Yield) 산출 불가.
A12: I | B12: 관리비(원,VAT별도) | C12: R2 | D12: 권장 | E12: 원 (VAT 별도) | F12: 월 관리비 청구액. 원 단위 숫자만. | G12: mgmt_fee_manwon (÷10,000) | H12: mgmtFeeKrw | I12: R2 미달 — 월합계·관리비 포함 비용·NOI 계열 지표 보류.
A13: J | B13: 최초 계약일 | C13: R3 | D13: 조건부 | E13: 날짜 YYYY-MM-DD | F13: 이 임차인이 처음 입주한 날 (현 계약 시작일과 다릅니다). 상가 갱신요구권 10년은 이 날짜로 기산합니다. | G13: first_contract_date | H13: firstContractDate | I13: R3 미달 — 상가 갱신권 잔여 '확인 필요', 명도 시점 산출 불가.
A14: K | B14: 현 계약 시작일 | C14: R2 | D14: 권장 | E14: 날짜 YYYY-MM-DD | F14: 현재 유효한 계약의 시작일. | G14: lease_start | H14: currentStartDate | I14: 계약 기간 계산(경과 기간) 보류. 등급 판정에는 영향 없음.
... A28: Y | B28: 전용평당 월비용(자동) | C28: 자동 | D28: 자동 | E28: 원/전용평 | F28: = (월세 + 관리비) ÷ 전용면적(평, AF ÷ 3.305785). 임차인이 실제로 쓰는 면적 기준 실질 비용(NOC). | G28: (계산) | H28: calculateNocPerExclusivePyeong() | I28: —
A30: 해상도 정의
A31: 등급 | B31: 의미 | E31: 필수 입력 | F31: 열리는 기능
A32: R0 | B32: 미달 | E32: 임대중 호실의 업종·월세·만료일 누락 등 R1 요건 미충족 | F32: 렌트롤을 발행 수준으로 쓸 수 없음 — 보완 자료 요청
A33: R1 | B33: 발행 최소선 | E33: 호실/층 · 업종/상호 · 보증금 · 월세 · 만료일 · 임대상태 | F33: 렌트롤 표 · 만료 타임라인 · 총액 수익률
A34: R2 | B34: 분석 가능 | E34: R1 + 임대면적(전 호실) · 적용법령(전 호실) · 관리비(임대중) · (권장) 전용면적·현 계약 시작일 | F34: 평당 단가 · 층별 단가 · 환산보증금 · 상임법 판정 (전용면적까지 있으면 전용률·전용평당 월비용)
A35: R3 | B35: 정밀 실사 | E35: R2 + 최초계약일 · 대항력 (갱신요구권 행사는 주택 필수) | F35: 갱신요구권 · 명도 계획 · 임대료 정상화 시뮬
A37: 면적 4분모와 렌트롤 면적의 관계
B38: 대지면적 | E38: 토지 평당 매각가의 분모. 렌트롤에 입력하지 않음.
B39: 연면적 | E39: 건축물대장 총 바닥면적. 임대면적 합계와 같지 않음(주차장·기계실 등 제외) — 자동 동일시 금지.
B40: 임대면적 | E40: 렌트롤 C열. 임대료 단가·공실률의 분모. 임대면적 = 전용면적 + 공용면적 분담분.
B41: 전용면적 | E41: 렌트롤 D열. 전용률·전용평당 월비용의 분모. 전용률(%) = 전용면적 ÷ 임대면적 × 100.
A44: v1.4 추가 항목 (업로드 반영 필드명은 제안값 — 시스템 반영 필요)
A45: 열 | B45: 컬럼명 | C45: 해상도 | D45: 필수도 | E45: 입력 방식 · 단위 | F45: 설명 | G45: 업로드 반영 필드 | H45: 도메인 필드 (LeaseRow) | I45: 비었을 때 영향
A46: Z | B46: 근거 | C46: R3+ | D46: 권장 | E46: 드롭다운 계약서 원본/매도인 렌트롤/구두 | F46: 이 행 숫자의 확인 수준. IM 출처 배지로 출력. | G46: evidence_level | H46: evidenceLevel | I46: 근거 미기재로 집계, R3+ 미달.
A47: AA | B47: 렌트프리 잔여(개월) | C47: R3+ | D47: 선택 | E47: 숫자 ≥ 0 | F47: 남은 무상·할인 개월 수. | G47: rent_free_months | H47: rentFreeMonths | I47: 렌트프리 없음으로 간주.
A48: AB | B48: 입금 확인(최근12개월) | C48: R3+ | D48: 권장 | E48: 드롭다운 정상/연체/미확인 | F48: 통장 입금 대조 결과. | G48: payment_status | H48: paymentStatus | I48: 「입금 내역 미대조」로 출력.
A49: AC | B49: 만기 구간(자동) | C49: 자동 | D49: 자동 | E49: 텍스트 | F49: 평가 기준일 대비 만료 경과/12개월 내/12개월 초과. | G49: (계산) | H49: expiryBucket() | I49: —
A50: AD | B50: 금액 판정(자동) | C50: 자동 | D50: 자동 | E50: 텍스트 | F50: 단독·통합계약 금액 누락·중복 판정. R1·R2 판정에 사용. | G50: (계산) | H50: amountCheck() | I50: —
A51: J3 | B51: 매각(희망)가 | C51: IM | D51: 권장 | E51: 원 | F51: 수익률 정본 계산. | G51: asking_price_krw | H51: askingPriceKrw | I51: 수익률 보류.
A52: J4 | B52: 연면적 | C52: IM | D52: 권장 | E52: ㎡ 고정 (건축물대장, G9와 무관) | F52: 임대면적 합 대조. | G52: gfa_sqm | H52: gfaSqm | I52: 면적 대조 보류.
A53: J5:J7 · M5:M7 | B53: 시장 임대료 3칸 + 출처 | C53: R3+ | D53: 조건부 | E53: 원/전용평·월 + 텍스트 | F53: 1층·지상층·지하층 시장 임대료와 출처·조사일. | G53: market_rent_* | H53: marketRent | I53: 정상화 시뮬 불가.
A54: J8 · M8 | B54: 기타수입 + 내역 | C54: IM | D54: 선택 | E54: 원/월 + 텍스트 | F54: 주차·안테나·광고 등 임대료 외 수입. | G54: other_income_krw | H54: otherIncomeKrw | I54: 기타수입 0으로 간주.
A56: v1.5 추가 항목 (업로드 반영 필드명은 제안값 — 시스템 반영 필요)
A57: 열 | B57: 컬럼명 | C57: 해상도 | D57: 필수도 | E57: 입력 방식 · 단위 | F57: 설명 | G57: 업로드 반영 필드 | H57: 도메인 필드 (LeaseRow) | I57: 비었을 때 영향
A58: G9 | B58: 면적 입력 단위 | C58: — | D58: 필수 | E58: 드롭다운 ㎡/평 (기본 ㎡) | F58: C·D열 면적을 어떤 단위로 적었는지. 파일당 1개. | G58: area_input_unit | H58: areaInputUnit | I58: ㎡로 간주.
...
