Workbook

Sheet 기입요령
A1: CREDEAL 렌트롤 표준 양식 v1.3 — 기입요령
A3: 모바일 IM 업로드용 표준 양식입니다. 「렌트롤」 시트의 노란색 셀만 입력하세요. (1행 = 1호실, 최대 100호실)
A5: 계약그룹이란? — 한 임차인이 한 계약서로 여러 호실·층을 쓰는 경우 (통합계약)
A6: 뜻 | B6: 하나의 임대차계약서로 한 임차인이 여러 호실(예: 1F+2F)을 쓸 때, 그 호실들을 한 묶음으로 표시하는 이름표입니다. 호실마다 따로 계약했다면 비워 두세요.
A7: 쓰는 법 | B7: 같은 계약에 속한 호실에는 같은 이름(A, B, 1 …)을 적습니다. 이름은 자유이며, 서로 다른 계약은 다른 이름으로 구분합니다.
A8: 금액은 대표 행에만 | B8: 보증금·월세·관리비는 묶음 중 한 행(대표 행)에만 적고 나머지 행은 비웁니다. 면적(임대·전용)·호실/층·업종/상호·임대상태·만료일은 행마다 적습니다.
A9: 예시 (설명용) | B9: 1F │ 그룹 A │ 임대 100㎡ │ ○○카페 │ 보증금·월세 입력 ← 대표 행 2F │ 그룹 A │ 임대 80㎡ │ ○○카페 │ 보증금·월세 비움 ← 같은 계약 3F │ (비움) │ 임대 90㎡ │ △△법무법인 │ 보증금·월세 입력 ← 단독 계약
A10: 왜 필요한가 | B10: 금액을 층마다 쪼개 적으면 한 계약이 여러 건으로 집계되고 환산보증금(상가법 적용 판정)이 쪼개져 틀어집니다. 대표 행에만 적으면 합계·환산보증금이 계약 1건으로 계산됩니다.
A11: IM에서의 표기 | B11: IM 렌트롤 표에서 같은 그룹의 금액 빈 행은 보증금·월임대료·관리비·월합계가 「〃」(위와 동일 계약)로 표시되고, 합계에는 대표 행 금액만 더해집니다. 계약그룹은 업로드 후 원장(lease_ledger)에도 저장됩니다.
A13: 색상 규칙
A14: 노란색 | B14: 입력 셀 — 여기만 채웁니다.
A15: 회색 | B15: 자동계산 — 수식이 들어 있으니 건드리지 마세요.
A16: 파랑/주황/분홍 (11행) | B16: 해상도 표시: 주황=R1 발행 최소선 · 파랑=R2 분석 가능 · 분홍=R3 정밀 실사. 자세한 정의는 「컬럼정의」 시트.
A18: 해상도(R1·R2·R3) — 채울수록 열리는 기능이 늘어납니다
A19: R1 최소형 | B19: 호실·업종·보증금·월세·만료일·임대상태 → 렌트롤 표 · 만료 타임라인 · 총액 수익률
A20: R2 필요형 | B20: R1 + 임대면적·적용법령·관리비 → 평당 단가 · 층별 단가 · 환산보증금 · 상임법 판정
A21: R3 표준형 | B21: R2 + 최초 계약일·대항력 → 갱신요구권 · 명도 계획 · 임대료 정상화 시뮬
A22: 면적 보강 (등급 무관) | B22: 전 호실 전용면적 입력(전용 ≤ 임대) → 전용률 · 전용평당 월비용(NOC)
A24: 면적 3종 — 임대면적 · 전용면적 · 전용률
A25: 임대면적 (C열) | B25: 임대차계약서에 적힌 계약면적(㎡). 전용면적 + 공용면적 분담분입니다. 임대료 평당 단가·공실률의 분모이며, 공실·자가사용 호실도 적습니다.
A26: 전용면적 (D열) | B26: 임차인이 독점해 사용하는 면적(㎡). 건축물대장 전유부 면적과 대조하세요. 임대면적보다 클 수 없습니다.
A27: 전용률 (S열, 자동) | B27: 전용면적 ÷ 임대면적 × 100. 직접 입력하지 마세요. 합계 행(10행)의 전용률은 평균이 아니라 Σ전용 ÷ Σ임대(두 면적이 모두 있는 호실만)입니다.
A28: 단위 | B28: 면적은 ㎡로만 입력합니다. 평 환산은 Q·R열이 자동 계산합니다. 평으로 적으면 면적이 3.3배 어긋납니다.
A29: IM 표 표기 | B29: IM 렌트롤 표에는 입력한 면적만 나옵니다. 임대·전용면적을 모두 적으면 두 열, 하나만 적으면 그 열 하나만 표시합니다. 한 면적을 다른 면적 값으로 대신 채우지 않고, 비워 둔 호실은 「-」로 표시합니다.
A30: 전용면적을 모를 때 | B30: 임대면적만 입력해도 업로드됩니다. 전용률·전용평당 월비용만 보류되고 IM 표에는 임대면적 열만 나옵니다 (「자동검증」에 미기재 호실 수가 표시됩니다).
A32: 반드시 채워야 하는 항목 (R1)
A33: 호실/층 | B33: 원본 표기 그대로. 「9F(1)」처럼 한 층에 둘이면 행을 나눠 적습니다.
A34: 업종/상호 (원문) | B34: ⚠ 계약서·렌트롤에 적힌 문구를 그대로 옮깁니다. 「사무실」이면 「사무실」입니다. 업종을 추측해 바꾸지 마세요.
A35: 임대상태 | B35: 임대중 / 공실 / 자가사용. 소유자가 직접 쓰는 층은 「자가사용」 — 공실이 아니지만 임대수입도 없습니다.
A36: 보증금·월세·관리비 | B36: 원 단위 숫자만. VAT 별도. 「5,000만」처럼 적지 마세요 (5,000만원 → 50000000).
A37: 현 계약 만료일 | B37: 명도 시점·만기 스케줄 산출의 기준입니다. 날짜 형식은 YYYY-MM-DD.
A39: 비면 판정이 보류되는 항목 (R2·R3)
A40: 적용법령 (R2) | B40: 상가 / 주택 / 미확인. 주거로 쓰는 오피스텔은 「주택」입니다. 이 값에 따라 갱신요구권 계산이 완전히 달라집니다.
A41: 최초 계약일 (R3) | B41: 이 임차인이 처음 입주한 날. 현 계약 시작일과 다릅니다. ★ 상가 갱신요구권 10년은 이 날짜로 기산합니다. 비면 「확인 필요」로 출력됩니다.
A42: 갱신요구권 행사 (R3) | B42: 있음 / 없음 / 모름. ★ 주택은 1회 한정이라 이 값 없이는 계산할 수 없습니다. 묵시적 갱신은 「없음」입니다 — 갱신요구권을 쓴 것이 아닙니다.
A43: 대항력 요건 (R3) | B43: 사업자등록 / 주민등록 / 미확인. 근거 없이 「없음」으로 적으면 발행이 막힙니다.
A45: 자주 나는 실수
A46: 업종 추측 | B46: 「사무실」을 「IT스타트업」으로 바꿔 적는 경우. 실제로 있었던 오류입니다.
A47: 면적 혼동 | B47: 전용면적을 임대면적 칸에 적거나 평 단위를 그대로 적는 경우. 전용률이 100%를 넘으면(빨간색) 두 칸이 바뀌었는지 확인하세요.
A48: 경과년수로 갱신권 역산 | B48: 주택은 최초계약일로 계산할 수 없습니다. 행사 이력이 있어야 합니다.
...

Sheet 렌트롤
A1: CREDEAL 렌트롤 표준 양식 v1.3
A2: 노란색 셀만 입력 · 회색은 자동계산 · 1행=1호실 · 면적 ㎡ · 금액 원(VAT 별도) · 11행 R1/R2/R3 = 해상도(자세한 설명은 「컬럼정의」 시트)
A3: 물건명 | F3: ⚠ 렌트롤 기준일이 비면 신선도 판정을 할 수 없습니다
A4: 소재지 | F4: ※ 환산보증금: 서울 9억 · 과밀억제권역 6.9억 · 광역시 5.4억 · 그 밖 3.7억
A5: 렌트롤 기준일
A6: 평가 기준일 | C6: =TODAY() -> 46300 | F6: 기본값 =TODAY(). 과거 시점 기준으로 평가하려면 날짜를 직접 입력하세요.
A7: 환산보증금 지역기준(원) | C7: 900000000 | F7: 지역에 맞게 수정 (서울 900,000,000)
A8: 작성자
A9: 작성일
A10: 합계 (자동) | C10: =SUM(C13:C112) -> 132.5 | D10: =SUM(D13:D112) -> 99.4 | G10: =SUM(G13:G112) -> 50000000 | H10: =SUM(H13:H112) -> 4500000 | I10: =SUM(I13:I112) -> 550000 | Q10: =SUM(Q13:Q112) -> 40.081252 | R10: =SUM(R13:R112) -> 30.068501 | S10: =IFERROR(SUMIFS(D13:D112,C13:C112,">0",D13:D112,">0")/SUMIFS(C13:C112,C13:C112,">0",D13:D112,">0")*100,"") -> 75.018868 | X10: =SUM(X13:X112) -> 5050000
A11: R1 | B11: R2 | C11: R2 | D11: R2* | E11: R1 | F11: R2 | G11: R1 | H11: R1 | I11: R2 | J11: R3 | K11: R2 | L11: R1 | M11: R3 | N11: R3 | O11: R1 | P11: — | Q11: 자동 | R11: 자동 | S11: 자동 | T11: 자동 | U11: 자동 | V11: 자동 | W11: 자동 | X11: 자동 | Y11: 자동
A12: 호실/층 | B12: 계약그룹 | C12: 임대면적(㎡) | D12: 전용면적(㎡) | E12: 업종/상호 (원문) | F12: 적용법령 | G12: 보증금(원) | H12: 월세(원,VAT별도) | I12: 관리비(원,VAT별도) | J12: 최초 계약일 | K12: 현 계약 시작일 | L12: 현 계약 만료일 | M12: 갱신요구권 행사 | N12: 대항력 요건 | O12: 임대상태 | P12: 비고 | Q12: 임대면적(평) | R12: 전용면적(평) | S12: 전용률(%) | T12: 환산보증금(자동) | U12: 상임법 전면적용 | V12: 갱신권 잔여(자동) | W12: 계약 상태(자동) | X12: 월 총수입(자동) | Y12: 전용평당 월비용(자동)
A13: 3F | C13: 132.5 | D13: 99.4 | E13: 사무실 | F13: 상가 | G13: 50000000 | H13: 4500000 | I13: 550000 | J13: 45017 | K13: 45292 | L13: 46752 | M13: 모름 | N13: 사업자등록 | O13: 임대중 | P13: ← 예시 행입니다. 지우고 쓰세요 | Q13: =IF(OR($A13="",C13=""),"",C13/3.305785) -> 40.081252 | R13: =IF(OR($A13="",D13=""),"",D13/3.305785) -> 30.068501 | S13: =IF(OR($A13="",C13="",D13=""),"",IF(C13>0,D13/C13*100,"")) -> 75.018868 | T13: =IF(OR($A13="",O13<>"임대중",F13<>"상가",G13=""),"",G13+H13*100) -> 500000000 | U13: =IF(T13="","",IF(T13<=$C$7,"○ 전면적용","× 초과 (5%상한 미적용)")) -> ○ 전면적용 | V13: =IF(OR($A13="",O13<>"임대중"),"",IF(F13="상가",IF(J13="","확인 필요",TEXT(MAX(0,10-($C$6-J13)/365.25),"0.0")&"년"),IF(F13="주택",IF(M13="있음","소진(1회)",IF(M13="없음",IF(L13="","확인 필요",TEXT(EDATE(L13,24),"yyyy-mm")&"까지"),"확인 필요")),"확인 필요"))) -> 6.5년 | W13: =IF($A13="","",IF(O13="공실","공실",IF(O13="자가사용","자가사용",IF(L13="","만료일 없음",IF(L13<$C$6,"만료 +"&TEXT($C$6-L13,"0")&"일",IF(L13-$C$6<=30,"임박 "&TEXT(L13-$C$6,"0")&"일","유효")))))) -> 유효 | X13: =IF(OR($A13="",O13<>"임대중"),"",IF(H13="",0,H13)+IF(I13="",0,I13)) -> 5050000 | Y13: =IF(OR($A13="",O13<>"임대중",D13="",H13=""),"",ROUND((H13+IF(I13="",0,I13))/(D13/3.305785),0)) -> 167950
Q14: =IF(OR($A14="",C14=""),"",C14/3.305785) | R14: =IF(OR($A14="",D14=""),"",D14/3.305785) | S14: =IF(OR($A14="",C14="",D14=""),"",IF(C14>0,D14/C14*100,"")) | T14: =IF(OR($A14="",O14<>"임대중",F14<>"상가",G14=""),"",G14+H14*100) | U14: =IF(T14="","",IF(T14<=$C$7,"○ 전면적용","× 초과 (5%상한 미적용)")) | V14: =IF(OR($A14="",O14<>"임대중"),"",IF(F14="상가",IF(J14="","확인 필요",TEXT(MAX(0,10-($C$6-J14)/365.25),"0.0")&"년"),IF(F14="주택",IF(M14="있음","소진(1회)",IF(M14="없음",IF(L14="","확인 필요",TEXT(EDATE(L14,24),"yyyy-mm")&"까지"),"확인 필요")),"확인 필요"))) | W14: =IF($A14="","",IF(O14="공실","공실",IF(O14="자가사용","자가사용",IF(L14="","만료일 없음",IF(L14<$C$6,"만료 +"&TEXT($C$6-L14,"0")&"일",IF(L14-$C$6<=30,"임박 "&TEXT(L14-$C$6,"0")&"일","유효")))))) | X14: =IF(OR($A14="",O14<>"임대중"),"",IF(H14="",0,H14)+IF(I14="",0,I14)) | Y14: =IF(OR($A14="",O14<>"임대중",D14="",H14=""),"",ROUND((H14+IF(I14="",0,I14))/(D14/3.305785),0))
Q15: =IF(OR($A15="",C15=""),"",C15/3.305785) | R15: =IF(OR($A15="",D15=""),"",D15/3.305785) | S15: =IF(OR($A15="",C15="",D15=""),"",IF(C15>0,D15/C15*100,"")) | T15: =IF(OR($A15="",O15<>"임대중",F15<>"상가",G15=""),"",G15+H15*100) | U15: =IF(T15="","",IF(T15<=$C$7,"○ 전면적용","× 초과 (5%상한 미적용)")) | V15: =IF(OR($A15="",O15<>"임대중"),"",IF(F15="상가",IF(J15="","확인 필요",TEXT(MAX(0,10-($C$6-J15)/365.25),"0.0")&"년"),IF(F15="주택",IF(M15="있음","소진(1회)",IF(M15="없음",IF(L15="","확인 필요",TEXT(EDATE(L15,24),"yyyy-mm")&"까지"),"확인 필요")),"확인 필요"))) | W15: =IF($A15="","",IF(O15="공실","공실",IF(O15="자가사용","자가사용",IF(L15="","만료일 없음",IF(L15<$C$6,"만료 +"&TEXT($C$6-L15,"0")&"일",IF(L15-$C$6<=30,"임박 "&TEXT(L15-$C$6,"0")&"일","유효")))))) | X15: =IF(OR($A15="",O15<>"임대중"),"",IF(H15="",0,H15)+IF(I15="",0,I15)) | Y15: =IF(OR($A15="",O15<>"임대중",D15="",H15=""),"",ROUND((H15+IF(I15="",0,I15))/(D15/3.305785),0))
Q16: =IF(OR($A16="",C16=""),"",C16/3.305785) | R16: =IF(OR($A16="",D16=""),"",D16/3.305785) | S16: =IF(OR($A16="",C16="",D16=""),"",IF(C16>0,D16/C16*100,"")) | T16: =IF(OR($A16="",O16<>"임대중",F16<>"상가",G16=""),"",G16+H16*100) | U16: =IF(T16="","",IF(T16<=$C$7,"○ 전면적용","× 초과 (5%상한 미적용)")) | V16: =IF(OR($A16="",O16<>"임대중"),"",IF(F16="상가",IF(J16="","확인 필요",TEXT(MAX(0,10-($C$6-J16)/365.25),"0.0")&"년"),IF(F16="주택",IF(M16="있음","소진(1회)",IF(M16="없음",IF(L16="","확인 필요",TEXT(EDATE(L16,24),"yyyy-mm")&"까지"),"확인 필요")),"확인 필요"))) | W16: =IF($A16="","",IF(O16="공실","공실",IF(O16="자가사용","자가사용",IF(L16="","만료일 없음",IF(L16<$C$6,"만료 +"&TEXT($C$6-L16,"0")&"일",IF(L16-$C$6<=30,"임박 "&TEXT(L16-$C$6,"0")&"일","유효")))))) | X16: =IF(OR($A16="",O16<>"임대중"),"",IF(H16="",0,H16)+IF(I16="",0,I16)) | Y16: =IF(OR($A16="",O16<>"임대중",D16="",H16=""),"",ROUND((H16+IF(I16="",0,I16))/(D16/3.305785),0))
Q17: =IF(OR($A17="",C17=""),"",C17/3.305785) | R17: =IF(OR($A17="",D17=""),"",D17/3.305785) | S17: =IF(OR($A17="",C17="",D17=""),"",IF(C17>0,D17/C17*100,"")) | T17: =IF(OR($A17="",O17<>"임대중",F17<>"상가",G17=""),"",G17+H17*100) | U17: =IF(T17="","",IF(T17<=$C$7,"○ 전면적용","× 초과 (5%상한 미적용)")) | V17: =IF(OR($A17="",O17<>"임대중"),"",IF(F17="상가",IF(J17="","확인 필요",TEXT(MAX(0,10-($C$6-J17)/365.25),"0.0")&"년"),IF(F17="주택",IF(M17="있음","소진(1회)",IF(M17="없음",IF(L17="","확인 필요",TEXT(EDATE(L17,24),"yyyy-mm")&"까지"),"확인 필요")),"확인 필요"))) | W17: =IF($A17="","",IF(O17="공실","공실",IF(O17="자가사용","자가사용",IF(L17="","만료일 없음",IF(L17<$C$6,"만료 +"&TEXT($C$6-L17,"0")&"일",IF(L17-$C$6<=30,"임박 "&TEXT(L17-$C$6,"0")&"일","유효")))))) | X17: =IF(OR($A17="",O17<>"임대중"),"",IF(H17="",0,H17)+IF(I17="",0,I17)) | Y17: =IF(OR($A17="",O17<>"임대중",D17="",H17=""),"",ROUND((H17+IF(I17="",0,I17))/(D17/3.305785),0))
Q18: =IF(OR($A18="",C18=""),"",C18/3.305785) | R18: =IF(OR($A18="",D18=""),"",D18/3.305785) | S18: =IF(OR($A18="",C18="",D18=""),"",IF(C18>0,D18/C18*100,"")) | T18: =IF(OR($A18="",O18<>"임대중",F18<>"상가",G18=""),"",G18+H18*100) | U18: =IF(T18="","",IF(T18<=$C$7,"○ 전면적용","× 초과 (5%상한 미적용)")) | V18: =IF(OR($A18="",O18<>"임대중"),"",IF(F18="상가",IF(J18="","확인 필요",TEXT(MAX(0,10-($C$6-J18)/365.25),"0.0")&"년"),IF(F18="주택",IF(M18="있음","소진(1회)",IF(M18="없음",IF(L18="","확인 필요",TEXT(EDATE(L18,24),"yyyy-mm")&"까지"),"확인 필요")),"확인 필요"))) | W18: =IF($A18="","",IF(O18="공실","공실",IF(O18="자가사용","자가사용",IF(L18="","만료일 없음",IF(L18<$C$6,"만료 +"&TEXT($C$6-L18,"0")&"일",IF(L18-$C$6<=30,"임박 "&TEXT(L18-$C$6,"0")&"일","유효")))))) | X18: =IF(OR($A18="",O18<>"임대중"),"",IF(H18="",0,H18)+IF(I18="",0,I18)) | Y18: =IF(OR($A18="",O18<>"임대중",D18="",H18=""),"",ROUND((H18+IF(I18="",0,I18))/(D18/3.305785),0))
Q19: =IF(OR($A19="",C19=""),"",C19/3.305785) | R19: =IF(OR($A19="",D19=""),"",D19/3.305785) | S19: =IF(OR($A19="",C19="",D19=""),"",IF(C19>0,D19/C19*100,"")) | T19: =IF(OR($A19="",O19<>"임대중",F19<>"상가",G19=""),"",G19+H19*100) | U19: =IF(T19="","",IF(T19<=$C$7,"○ 전면적용","× 초과 (5%상한 미적용)")) | V19: =IF(OR($A19="",O19<>"임대중"),"",IF(F19="상가",IF(J19="","확인 필요",TEXT(MAX(0,10-($C$6-J19)/365.25),"0.0")&"년"),IF(F19="주택",IF(M19="있음","소진(1회)",IF(M19="없음",IF(L19="","확인 필요",TEXT(EDATE(L19,24),"yyyy-mm")&"까지"),"확인 필요")),"확인 필요"))) | W19: =IF($A19="","",IF(O19="공실","공실",IF(O19="자가사용","자가사용",IF(L19="","만료일 없음",IF(L19<$C$6,"만료 +"&TEXT($C$6-L19,"0")&"일",IF(L19-$C$6<=30,"임박 "&TEXT(L19-$C$6,"0")&"일","유효")))))) | X19: =IF(OR($A19="",O19<>"임대중"),"",IF(H19="",0,H19)+IF(I19="",0,I19)) | Y19: =IF(OR($A19="",O19<>"임대중",D19="",H19=""),"",ROUND((H19+IF(I19="",0,I19))/(D19/3.305785),0))
Q20: =IF(OR($A20="",C20=""),"",C20/3.305785) | R20: =IF(OR($A20="",D20=""),"",D20/3.305785) | S20: =IF(OR($A20="",C20="",D20=""),"",IF(C20>0,D20/C20*100,"")) | T20: =IF(OR($A20="",O20<>"임대중",F20<>"상가",G20=""),"",G20+H20*100) | U20: =IF(T20="","",IF(T20<=$C$7,"○ 전면적용","× 초과 (5%상한 미적용)")) | V20: =IF(OR($A20="",O20<>"임대중"),"",IF(F20="상가",IF(J20="","확인 필요",TEXT(MAX(0,10-($C$6-J20)/365.25),"0.0")&"년"),IF(F20="주택",IF(M20="있음","소진(1회)",IF(M20="없음",IF(L20="","확인 필요",TEXT(EDATE(L20,24),"yyyy-mm")&"까지"),"확인 필요")),"확인 필요"))) | W20: =IF($A20="","",IF(O20="공실","공실",IF(O20="자가사용","자가사용",IF(L20="","만료일 없음",IF(L20<$C$6,"만료 +"&TEXT($C$6-L20,"0")&"일",IF(L20-$C$6<=30,"임박 "&TEXT(L20-$C$6,"0")&"일","유효")))))) | X20: =IF(OR($A20="",O20<>"임대중"),"",IF(H20="",0,H20)+IF(I20="",0,I20)) | Y20: =IF(OR($A20="",O20<>"임대중",D20="",H20=""),"",ROUND((H20+IF(I20="",0,I20))/(D20/3.305785),0))
Q21: =IF(OR($A21="",C21=""),"",C21/3.305785) | R21: =IF(OR($A21="",D21=""),"",D21/3.305785) | S21: =IF(OR($A21="",C21="",D21=""),"",IF(C21>0,D21/C21*100,"")) | T21: =IF(OR($A21="",O21<>"임대중",F21<>"상가",G21=""),"",G21+H21*100) | U21: =IF(T21="","",IF(T21<=$C$7,"○ 전면적용","× 초과 (5%상한 미적용)")) | V21: =IF(OR($A21="",O21<>"임대중"),"",IF(F21="상가",IF(J21="","확인 필요",TEXT(MAX(0,10-($C$6-J21)/365.25),"0.0")&"년"),IF(F21="주택",IF(M21="있음","소진(1회)",IF(M21="없음",IF(L21="","확인 필요",TEXT(EDATE(L21,24),"yyyy-mm")&"까지"),"확인 필요")),"확인 필요"))) | W21: =IF($A21="","",IF(O21="공실","공실",IF(O21="자가사용","자가사용",IF(L21="","만료일 없음",IF(L21<$C$6,"만료 +"&TEXT($C$6-L21,"0")&"일",IF(L21-$C$6<=30,"임박 "&TEXT(L21-$C$6,"0")&"일","유효")))))) | X21: =IF(OR($A21="",O21<>"임대중"),"",IF(H21="",0,H21)+IF(I21="",0,I21)) | Y21: =IF(OR($A21="",O21<>"임대중",D21="",H21=""),"",ROUND((H21+IF(I21="",0,I21))/(D21/3.305785),0))
Q22: =IF(OR($A22="",C22=""),"",C22/3.305785) | R22: =IF(OR($A22="",D22=""),"",D22/3.305785) | S22: =IF(OR($A22="",C22="",D22=""),"",IF(C22>0,D22/C22*100,"")) | T22: =IF(OR($A22="",O22<>"임대중",F22<>"상가",G22=""),"",G22+H22*100) | U22: =IF(T22="","",IF(T22<=$C$7,"○ 전면적용","× 초과 (5%상한 미적용)")) | V22: =IF(OR($A22="",O22<>"임대중"),"",IF(F22="상가",IF(J22="","확인 필요",TEXT(MAX(0,10-($C$6-J22)/365.25),"0.0")&"년"),IF(F22="주택",IF(M22="있음","소진(1회)",IF(M22="없음",IF(L22="","확인 필요",TEXT(EDATE(L22,24),"yyyy-mm")&"까지"),"확인 필요")),"확인 필요"))) | W22: =IF($A22="","",IF(O22="공실","공실",IF(O22="자가사용","자가사용",IF(L22="","만료일 없음",IF(L22<$C$6,"만료 +"&TEXT($C$6-L22,"0")&"일",IF(L22-$C$6<=30,"임박 "&TEXT(L22-$C$6,"0")&"일","유효")))))) | X22: =IF(OR($A22="",O22<>"임대중"),"",IF(H22="",0,H22)+IF(I22="",0,I22)) | Y22: =IF(OR($A22="",O22<>"임대중",D22="",H22=""),"",ROUND((H22+IF(I22="",0,I22))/(D22/3.305785),0))
Q23: =IF(OR($A23="",C23=""),"",C23/3.305785) | R23: =IF(OR($A23="",D23=""),"",D23/3.305785) | S23: =IF(OR($A23="",C23="",D23=""),"",IF(C23>0,D23/C23*100,"")) | T23: =IF(OR($A23="",O23<>"임대중",F23<>"상가",G23=""),"",G23+H23*100) | U23: =IF(T23="","",IF(T23<=$C$7,"○ 전면적용","× 초과 (5%상한 미적용)")) | V23: =IF(OR($A23="",O23<>"임대중"),"",IF(F23="상가",IF(J23="","확인 필요",TEXT(MAX(0,10-($C$6-J23)/365.25),"0.0")&"년"),IF(F23="주택",IF(M23="있음","소진(1회)",IF(M23="없음",IF(L23="","확인 필요",TEXT(EDATE(L23,24),"yyyy-mm")&"까지"),"확인 필요")),"확인 필요"))) | W23: =IF($A23="","",IF(O23="공실","공실",IF(O23="자가사용","자가사용",IF(L23="","만료일 없음",IF(L23<$C$6,"만료 +"&TEXT($C$6-L23,"0")&"일",IF(L23-$C$6<=30,"임박 "&TEXT(L23-$C$6,"0")&"일","유효")))))) | X23: =IF(OR($A23="",O23<>"임대중"),"",IF(H23="",0,H23)+IF(I23="",0,I23)) | Y23: =IF(OR($A23="",O23<>"임대중",D23="",H23=""),"",ROUND((H23+IF(I23="",0,I23))/(D23/3.305785),0))
Q24: =IF(OR($A24="",C24=""),"",C24/3.305785) | R24: =IF(OR($A24="",D24=""),"",D24/3.305785) | S24: =IF(OR($A24="",C24="",D24=""),"",IF(C24>0,D24/C24*100,"")) | T24: =IF(OR($A24="",O24<>"임대중",F24<>"상가",G24=""),"",G24+H24*100) | U24: =IF(T24="","",IF(T24<=$C$7,"○ 전면적용","× 초과 (5%상한 미적용)")) | V24: =IF(OR($A24="",O24<>"임대중"),"",IF(F24="상가",IF(J24="","확인 필요",TEXT(MAX(0,10-($C$6-J24)/365.25),"0.0")&"년"),IF(F24="주택",IF(M24="있음","소진(1회)",IF(M24="없음",IF(L24="","확인 필요",TEXT(EDATE(L24,24),"yyyy-mm")&"까지"),"확인 필요")),"확인 필요"))) | W24: =IF($A24="","",IF(O24="공실","공실",IF(O24="자가사용","자가사용",IF(L24="","만료일 없음",IF(L24<$C$6,"만료 +"&TEXT($C$6-L24,"0")&"일",IF(L24-$C$6<=30,"임박 "&TEXT(L24-$C$6,"0")&"일","유효")))))) | X24: =IF(OR($A24="",O24<>"임대중"),"",IF(H24="",0,H24)+IF(I24="",0,I24)) | Y24: =IF(OR($A24="",O24<>"임대중",D24="",H24=""),"",ROUND((H24+IF(I24="",0,I24))/(D24/3.305785),0))
Q25: =IF(OR($A25="",C25=""),"",C25/3.305785) | R25: =IF(OR($A25="",D25=""),"",D25/3.305785) | S25: =IF(OR($A25="",C25="",D25=""),"",IF(C25>0,D25/C25*100,"")) | T25: =IF(OR($A25="",O25<>"임대중",F25<>"상가",G25=""),"",G25+H25*100) | U25: =IF(T25="","",IF(T25<=$C$7,"○ 전면적용","× 초과 (5%상한 미적용)")) | V25: =IF(OR($A25="",O25<>"임대중"),"",IF(F25="상가",IF(J25="","확인 필요",TEXT(MAX(0,10-($C$6-J25)/365.25),"0.0")&"년"),IF(F25="주택",IF(M25="있음","소진(1회)",IF(M25="없음",IF(L25="","확인 필요",TEXT(EDATE(L25,24),"yyyy-mm")&"까지"),"확인 필요")),"확인 필요"))) | W25: =IF($A25="","",IF(O25="공실","공실",IF(O25="자가사용","자가사용",IF(L25="","만료일 없음",IF(L25<$C$6,"만료 +"&TEXT($C$6-L25,"0")&"일",IF(L25-$C$6<=30,"임박 "&TEXT(L25-$C$6,"0")&"일","유효")))))) | X25: =IF(OR($A25="",O25<>"임대중"),"",IF(H25="",0,H25)+IF(I25="",0,I25)) | Y25: =IF(OR($A25="",O25<>"임대중",D25="",H25=""),"",ROUND((H25+IF(I25="",0,I25))/(D25/3.305785),0))
... Q112: =IF(OR($A112="",C112=""),"",C112/3.305785) | R112: =IF(OR($A112="",D112=""),"",D112/3.305785) | S112: =IF(OR($A112="",C112="",D112=""),"",IF(C112>0,D112/C112*100,"")) | T112: =IF(OR($A112="",O112<>"임대중",F112<>"상가",G112=""),"",G112+H112*100) | U112: =IF(T112="","",IF(T112<=$C$7,"○ 전면적용","× 초과 (5%상한 미적용)")) | V112: =IF(OR($A112="",O112<>"임대중"),"",IF(F112="상가",IF(J112="","확인 필요",TEXT(MAX(0,10-($C$6-J112)/365.25),"0.0")&"년"),IF(F112="주택",IF(M112="있음","소진(1회)",IF(M112="없음",IF(L112="","확인 필요",TEXT(EDATE(L112,24),"yyyy-mm")&"까지"),"확인 필요")),"확인 필요"))) | W112: =IF($A112="","",IF(O112="공실","공실",IF(O112="자가사용","자가사용",IF(L112="","만료일 없음",IF(L112<$C$6,"만료 +"&TEXT($C$6-L112,"0")&"일",IF(L112-$C$6<=30,"임박 "&TEXT(L112-$C$6,"0")&"일","유효")))))) | X112: =IF(OR($A112="",O112<>"임대중"),"",IF(H112="",0,H112)+IF(I112="",0,I112)) | Y112: =IF(OR($A112="",O112<>"임대중",D112="",H112=""),"",ROUND((H112+IF(I112="",0,I112))/(D112/3.305785),0))

Sheet 자동검증
A1: 자동 검증 — 발행 전 확인
A3: # | B3: 검증 항목 | C3: 결과 | D3: 판정 기준
A4: G19 | B4: 렌트롤 월세 합계 (정본) | C4: =TEXT(SUM('렌트롤'!$H$13:$H$112),"#,##0")&"원" | D4: 표지 요약과 다르면 발행 차단. 이 표가 정본입니다.
A5: C19 | B5: 임대면적 합계 | C5: =TEXT(SUM('렌트롤'!$C$13:$C$112),"#,##0.00")&"㎡ / "&TEXT(SUM('렌트롤'!$Q$13:$Q$112),"#,##0.0")&"평" | D5: 건축물대장 연면적과 대조. 불일치 시 원인 규명 전까지 발행 보류.
A6: C19-E | B6: 전용면적 합계 | C6: =TEXT(SUM('렌트롤'!$D$13:$D$112),"#,##0.00")&"㎡ / "&TEXT(SUM('렌트롤'!$R$13:$R$112),"#,##0.0")&"평" | D6: 건축물대장 전유면적 합계와 0.5% 이내 일치해야 합니다 (A01 경고 기준).
A7: C19-R | B7: 가중 전용률 | C7: =IF('렌트롤'!$S$10="","산출 불가 (임대·전용면적 쌍 없음)",TEXT('렌트롤'!$S$10,"0.0")&"%") | D7: Σ전용면적 ÷ Σ임대면적 (두 면적이 모두 있는 호실만). 호실별 전용률의 단순 평균이 아닙니다.
A8: C19-M | B8: 임대면적 미기재 호실 | C8: =COUNTIFS('렌트롤'!$A$13:$A$112,"<>",'렌트롤'!$C$13:$C$112,"")&"건" | D8: 1건 이상이면 R2 미달 — 평당 단가·면적 공실률 산출 불가.
A9: C19-X | B9: 전용면적 미기재 호실 | C9: =COUNTIFS('렌트롤'!$A$13:$A$112,"<>",'렌트롤'!$D$13:$D$112,"")&"건" | D9: 1건 이상이면 전용률·전용평당 월비용 보류. (공실 호실 포함)
A10: C19-V | B10: 전용률 이상치 | C10: =COUNTIF('렌트롤'!$S$13:$S$112,">100")&"건 100% 초과 / "&COUNTIF('렌트롤'!$S$13:$S$112,"<30")&"건 30% 미만" | D10: 100% 초과 = 전용면적이 임대면적보다 큰 입력 오류(발행 보류). 30% 미만 = 면적 기재 오류 의심.
A11: F11 | B11: 만료 계약 수 | C11: =COUNTIF('렌트롤'!$W$13:$W$112,"만료*")&" / "&COUNTIF('렌트롤'!$O$13:$O$112,"임대중")&"건" | D11: 1건 이상이면 호실별 경고.
A12: F12 | B12: 만료 비율 50% 초과 | C12: =IF(COUNTIF('렌트롤'!$W$13:$W$112,"만료*")>COUNTIF('렌트롤'!$O$13:$O$112,"임대중")/2,"발행 차단","통과") | D12: 절반 초과 시 렌트롤 갱신 전까지 발행 불가.
A13: F13 | B13: 30일 내 만료 임박 | C13: =COUNTIF('렌트롤'!$W$13:$W$112,"임박*")&"건" | D13: 재계약 조건이 딜 구조를 바꿉니다. 협의 상태 확인 필요.
A14: G18 | B14: 갱신권 판정 보류 | C14: =COUNTIF('렌트롤'!$V$13:$V$112,"확인 필요")&"건" | D14: 최초계약일(상가)·행사이력(주택) 누락. 숫자 대신 "확인 필요" 출력.
A15: G13 | B15: 대항력 미확인 | C15: =COUNTIF('렌트롤'!$N$13:$N$112,"미확인")&"건" | D15: 근거 없이 "없음" 표기 시 발행 차단.
A16: G17 | B16: 업종 미기재 | C16: =COUNTIFS('렌트롤'!$A$13:$A$112,"<>",'렌트롤'!$E$13:$E$112,"")&"건" | D16: 비면 "미상"으로 출력. 추론 금지.
A17: T-C | B17: 환산보증금 초과 호실 | C17: =COUNTIF('렌트롤'!$U$13:$U$112,"×*")&"건" | D17: 초과 시 5% 인상상한·우선변제권 미적용. 갱신요구권은 적용됨.
A18: F01 | B18: 렌트롤 기준일 | C18: =IF('렌트롤'!$C$5="","미기재",TEXT('렌트롤'!$C$5,"yyyy-mm-dd")) | D18: 없으면 신선도 판정 불가.
A19: C21 | B19: 공실 / 자가사용 | C19: =COUNTIF('렌트롤'!$O$13:$O$112,"공실")&"건 / "&COUNTIF('렌트롤'!$O$13:$O$112,"자가사용")&"건" | D19: 자가사용은 임대 전환 여력. 공실 손실과 구분합니다.
A21: 해상도 판정 — 이 렌트롤로 무엇을 만들 수 있나
A22: 등급 | B22: 요건 | C22: 충족 | D22: 열리는 기능
A23: R1 최소형 | B23: 호실·업종·월세·만료일·임대상태 (임대중 호실 전부) | C23: =IF(AND(COUNTA('렌트롤'!$A$13:$A$112)>0,COUNTA('렌트롤'!$O$13:$O$112)=COUNTA('렌트롤'!$A$13:$A$112),COUNTIFS('렌트롤'!$O$13:$O$112,"임대중",'렌트롤'!$E$13:$E$112,"<>")=COUNTIF('렌트롤'!$O$13:$O$112,"임대중"),COUNTIFS('렌트롤'!$O$13:$O$112,"임대중",'렌트롤'!$H$13:$H$112,"<>")=COUNTIF('렌트롤'!$O$13:$O$112,"임대중"),COUNTIFS('렌트롤'!$O$13:$O$112,"임대중",'렌트롤'!$L$13:$L$112,"<>")=COUNTIF('렌트롤'!$O$13:$O$112,"임대중")),"충족","미달") | D23: 렌트롤 표 · 만료 타임라인 · 총액 수익률
A24: R2 필요형 | B24: R1 + 임대면적(전 호실)·적용법령(전 호실)·관리비(임대중) | C24: =IF(AND(C23="충족",COUNTA('렌트롤'!$C$13:$C$112)=COUNTA('렌트롤'!$A$13:$A$112),COUNTA('렌트롤'!$F$13:$F$112)=COUNTA('렌트롤'!$A$13:$A$112),COUNTIFS('렌트롤'!$O$13:$O$112,"임대중",'렌트롤'!$I$13:$I$112,"<>")=COUNTIF('렌트롤'!$O$13:$O$112,"임대중")),"충족","미달") | D24: 평당 단가 · 층별 단가 · 환산보증금 · 상임법 판정
A25: R3 표준형 | B25: R2 + 최초계약일·대항력 (임대중 호실 전부, '미확인' 불가) | C25: =IF(AND(C24="충족",COUNTIFS('렌트롤'!$O$13:$O$112,"임대중",'렌트롤'!$J$13:$J$112,"<>")=COUNTIF('렌트롤'!$O$13:$O$112,"임대중"),COUNTIFS('렌트롤'!$O$13:$O$112,"임대중",'렌트롤'!$N$13:$N$112,"<>")=COUNTIF('렌트롤'!$O$13:$O$112,"임대중"),COUNTIFS('렌트롤'!$O$13:$O$112,"임대중",'렌트롤'!$N$13:$N$112,"미확인")=0),"충족","미달") | D25: 갱신요구권 · 명도 계획 · 임대료 정상화 시뮬
A26: 면적 보강 | B26: 전 호실 임대면적·전용면적 입력, 전용률 100% 이하 (등급 무관) | C26: =IF(AND(COUNTA('렌트롤'!$A$13:$A$112)>0,COUNTA('렌트롤'!$C$13:$C$112)=COUNTA('렌트롤'!$A$13:$A$112),COUNTA('렌트롤'!$D$13:$D$112)=COUNTA('렌트롤'!$A$13:$A$112),COUNTIF('렌트롤'!$S$13:$S$112,">100")=0),"충족","미달") | D26: 전용률 · 전용평당 월비용(NOC)
B28: 현재 해상도 | C28: =IF(C25="충족","R3 표준형",IF(C24="충족","R2 필요형",IF(C23="충족","R1 최소형","R0 미달")))
B29: 다음 한 칸 | C29: =IF(C23<>"충족","「업종」「월세」「현 계약 만료일」「임대상태」부터 채우세요. 렌트롤 표를 그릴 수 없습니다",IF(C24<>"충족","「적용법령」「관리비」를 채우면 환산보증금·상임법 판정이 열립니다. 「임대면적」은 평당 단가를 엽니다",IF(C25<>"충족","「최초 계약일」과 「대항력 요건」을 채우면 갱신요구권·명도 계획이 열립니다",IF(C26<>"충족","「전용면적」을 모든 호실에 채우면 전용률·전용평당 월비용이 열립니다","완료 — 모든 기능 사용 가능"))))
B31: ※ 이 시트는 참고용입니다. 시스템은 '렌트롤' 시트를 자동으로 읽습니다.

Sheet 컬럼정의
A1: 컬럼 정의 — R1 / R2 / R3 해상도별 입력 항목과 설명
A2: 해상도 = 이 렌트롤로 만들 수 있는 분석의 깊이. 판정 로직: src/domain/building/mobile-im/lease-math.ts resolveLedger(). R0은 R1 요건 미달.
A3: 열 | B3: 컬럼명 | C3: 해상도 | D3: 필수도 | E3: 입력 방식 · 단위 | F3: 설명 | G3: 업로드 반영 필드 | H3: 도메인 필드 (LeaseRow) | I3: 비었을 때 영향
A4: A | B4: 호실/층 | C4: R1 | D4: 필수 | E4: 텍스트 | F4: 원본 표기 그대로 (예: B1, 1F, 101호). 한 층에 호실이 둘이면 행을 나눠 적습니다. | G4: floor | H4: unitLabel | I4: 행 식별 불가 — 층 라벨이 'N F'로 대체됩니다.
A5: B | B5: 계약그룹 | C5: R2 | D5: 조건부 | E5: 텍스트 | F5: 통합계약 표시. 한 임차인이 한 계약서로 여러 호실·층을 쓸 때, 그 호실들에 같은 이름(A, B, 1…)을 적습니다. 보증금·월세·관리비는 대표 행 한 곳에만 적고 나머지 행은 비웁니다(면적·만료일 등은 행마다 적음). 호실별로 따로 계약했다면 비워 두세요. | G5: contract_group | H5: contractGroup | I5: 통합계약 금액 중복 집계 위험(대표 행 외 금액을 비워 두면 영향 없음). 비우면 호실마다 별개 계약으로 취급됩니다.
A6: C | B6: 임대면적(㎡) | C6: R2 | D6: 권장 | E6: ㎡ (소수 2자리) | F6: 임대차계약서상 계약면적 = 전용면적 + 공용면적 분담분. 임대료 평당 단가·면적 기준 공실률의 분모입니다. 공실·자가사용 호실도 적습니다. | G6: area_sqm | H6: leaseAreaSqm | I6: R2 미달 — 평당 임대단가·면적 공실률·임대료 정상화 산출 불가.
A7: D | B7: 전용면적(㎡) | C7: R2* | D7: 권장 | E7: ㎡ (소수 2자리) | F7: 임차인이 독점해 사용하는 면적(건축물대장 전유부 기준). 임대면적보다 클 수 없습니다. 전용률과 전용평당 월비용의 분모입니다. (* 등급 판정에는 영향 없는 보강 항목) | G7: exclusive_area_sqm | H7: exclusiveAreaSqm | I7: 전용률·전용평당 월비용 보류. IM 렌트롤 표에서 전용면적 열이 빠지고 임대면적만 표기됩니다(다른 면적 값으로 대신 채우지 않음).
A8: E | B8: 업종/상호 (원문) | C8: R1 | D8: 필수 | E8: 텍스트 | F8: 계약서·렌트롤에 적힌 문구를 그대로 옮깁니다. 업종을 추측해 바꾸지 마세요. 공실이면 '공실'. | G8: tenant_type · tenant_name | H8: tenantBusiness | I8: R1 미달 — 렌트롤 표를 그릴 수 없고, 임대상태 미기재 시 공실로 추정됩니다.
A9: F | B9: 적용법령 | C9: R2 | D9: 권장 | E9: 드롭다운 상가/주택/미확인 | F9: 상가 / 주택 / 미확인. 주거로 쓰는 오피스텔은 '주택'. 갱신요구권 산식이 완전히 달라집니다. | G9: legal_basis | H9: legalBasis | I9: R2 미달 — 환산보증금·상임법 판정·갱신권 잔여 '확인 필요'.
A10: G | B10: 보증금(원) | C10: R1 | D10: 필수 | E10: 원 (VAT 별도) | F10: 원 단위 숫자만. '5,000만'처럼 적지 마세요 (5,000만원 → 50000000). | G10: deposit_manwon (÷10,000) | H10: depositKrw | I10: R1 미달 — 보증금 합계·환산보증금 산출 불가.
A11: H | B11: 월세(원,VAT별도) | C11: R1 | D11: 필수 | E11: 원 (VAT 별도) | F11: 월 임대료. VAT·관리비 제외. 원 단위 숫자만. | G11: rent_manwon (÷10,000) | H11: monthlyRentKrw | I11: R1 미달 — 임대수입·수익률(Gross Yield) 산출 불가.
A12: I | B12: 관리비(원,VAT별도) | C12: R2 | D12: 권장 | E12: 원 (VAT 별도) | F12: 월 관리비 청구액. 원 단위 숫자만. | G12: mgmt_fee_manwon (÷10,000) | H12: mgmtFeeKrw | I12: R2 미달 — 월합계·관리비 포함 비용·NOI 계열 지표 보류.
A13: J | B13: 최초 계약일 | C13: R3 | D13: 조건부 | E13: 날짜 YYYY-MM-DD | F13: 이 임차인이 처음 입주한 날 (현 계약 시작일과 다릅니다). 상가 갱신요구권 10년은 이 날짜로 기산합니다. | G13: first_contract_date | H13: firstContractDate | I13: R3 미달 — 상가 갱신권 잔여 '확인 필요', 명도 시점 산출 불가.
A14: K | B14: 현 계약 시작일 | C14: R2 | D14: 권장 | E14: 날짜 YYYY-MM-DD | F14: 현재 유효한 계약의 시작일. | G14: lease_start | H14: currentStartDate | I14: 계약 기간 계산(경과 기간) 보류. 등급 판정에는 영향 없음.
... A28: Y | B28: 전용평당 월비용(자동) | C28: 자동 | D28: 자동 | E28: 원/전용평 | F28: = (월세 + 관리비) ÷ 전용면적(평). 임차인이 실제로 쓰는 면적 기준 실질 비용(NOC). | G28: (계산) | H28: calculateNocPerExclusivePyeong() | I28: —
A30: 해상도 정의
A31: 등급 | B31: 의미 | E31: 필수 입력 | F31: 열리는 기능
A32: R0 | B32: 미달 | E32: 임대중 호실의 업종·월세·만료일 누락 등 R1 요건 미충족 | F32: 렌트롤을 발행 수준으로 쓸 수 없음 — 보완 자료 요청
A33: R1 | B33: 발행 최소선 | E33: 호실/층 · 업종/상호 · 보증금 · 월세 · 만료일 · 임대상태 | F33: 렌트롤 표 · 만료 타임라인 · 총액 수익률
A34: R2 | B34: 분석 가능 | E34: R1 + 임대면적(전 호실) · 적용법령(전 호실) · 관리비(임대중) · (권장) 전용면적·현 계약 시작일 | F34: 평당 단가 · 층별 단가 · 환산보증금 · 상임법 판정 (전용면적까지 있으면 전용률·전용평당 월비용)
A35: R3 | B35: 정밀 실사 | E35: R2 + 최초계약일 · 대항력 (갱신요구권 행사는 주택 필수) | F35: 갱신요구권 · 명도 계획 · 임대료 정상화 시뮬
A37: 면적 4분모와 렌트롤 면적의 관계
B38: 대지면적 | E38: 토지 평당 매각가의 분모. 렌트롤에 입력하지 않음.
B39: 연면적 | E39: 건축물대장 총 바닥면적. 임대면적 합계와 같지 않음(주차장·기계실 등 제외) — 자동 동일시 금지.
B40: 임대면적 | E40: 렌트롤 C열. 임대료 단가·공실률의 분모. 임대면적 = 전용면적 + 공용면적 분담분.
B41: 전용면적 | E41: 렌트롤 D열. 전용률·전용평당 월비용의 분모. 전용률(%) = 전용면적 ÷ 임대면적 × 100.
